Workbook
Name __bookmark_1: #REF!

Sheet 2026 Monthly Vacation
B2: Employee Info | G2: YTD Vacation | N2: 2026 Days Taken Off by Month
B3: Dept | C3: Job Title | D3: Name | E3: Start date | G3: Vacation Days | H3: Pro Rated Days | I3: Days Taken | J3: Unpaid Days Taken | K3: Days Remaining | L3: % Remaining | N3: January | O3: February | P3: March | Q3: April | R3: May | S3: June | T3: July | U3: August | V3: September | W3: October | X3: November | Y3: December
A4: 1 | B4: LT | C4: CEO | D4: Mazahreh, Said | E4: =_xlfn.XLOOKUP(D4,'Contract Entitlement'!$D$4:$D$61,'Contract Entitlement'!$G$4:$G$61) -> 0 | G4: 25 | H4: =IF(YEAR(E4)=2026,IF(DAY(E4)<15,CEILING(G4 * (12 - MONTH(E4) + 1) / 12,1),FLOOR(G4 * (12 - MONTH(E4) + 1) / 12,1)),IF(YEAR(E4)<2026,G4,0)) -> 25 | I4: =SUM(N4:Y4) -> 0 | J4: =COUNTIFS('2026 Time Off Request'!$A$2:$A$822,D4,'2026 Time Off Request'!$E$2:$E$822,"UNPAID") -> 0 | K4: =H4-I4 -> 25 | N4: =_xlfn.XLOOKUP($D4,'Jan 2026'!$D:$D,'Jan 2026'!$E:$E) -> 0 | O4: =_xlfn.XLOOKUP($D4,'Feb 2026'!$D:$D,'Feb 2026'!$E:$E) -> 0 | P4: =_xlfn.XLOOKUP($D4,'Mar 2026'!$D:$D,'Mar 2026'!$E:$E) -> 0 | Q4: =_xlfn.XLOOKUP($D4,'April 2026'!$D:$D,'April 2026'!$E:$E) -> 0 | R4: =_xlfn.XLOOKUP($D4,'May 2026'!$D:$D,'May 2026'!$E:$E) -> 0 | S4: =_xlfn.XLOOKUP($D4,'June 2026'!$D:$D,'June 2026'!$E:$E) -> 0 | T4: =_xlfn.XLOOKUP($D4,'July 2026'!$D:$D,'July 2026'!$E:$E) -> 0 | U4: =_xlfn.XLOOKUP($D4,'Aug 2026'!$D:$D,'Aug 2026'!$E:$E) -> 0 | V4: =_xlfn.XLOOKUP($D4,'Sept 2026'!$D:$D,'Sept 2026'!$E:$E) -> 0 | W4: =_xlfn.XLOOKUP($D4,'Oct 2026'!$D:$D,'Oct 2026'!$E:$E) -> 0 | X4: =_xlfn.XLOOKUP($D4,'Nov 2026'!$D:$D,'Nov 2026'!$E:$E) -> 0 | Y4: =_xlfn.XLOOKUP($D4,'Dec 2026'!$D:$D,'Dec 2026'!$E:$E) -> 0
A5: 2 | B5: LT | C5: Director of Finance | D5: Reid, Laurie | E5: =_xlfn.XLOOKUP(D5,'Contract Entitlement'!$D$4:$D$61,'Contract Entitlement'!$G$4:$G$61) -> 44243 | G5: =_xlfn.XLOOKUP(D5,'Contract Entitlement'!$D$4:$D$61,'Contract Entitlement'!$F$4:$F$61) -> 25 | H5: =IF(YEAR(E5)=2026,IF(DAY(E5)<15,CEILING(G5 * (12 - MONTH(E5) + 1) / 12,1),FLOOR(G5 * (12 - MONTH(E5) + 1) / 12,1)),IF(YEAR(E5)<2026,G5,0)) -> 25 | I5: =SUM(N5:Y5) -> 5 | J5: =COUNTIFS('2026 Time Off Request'!$A$2:$A$822,D5,'2026 Time Off Request'!$E$2:$E$822,"UNPAID") -> 0 | K5: =H5-I5 -> 20 | L5: =K5/G5 -> 0.8 | N5: =_xlfn.XLOOKUP($D5,'Jan 2026'!$D:$D,'Jan 2026'!$E:$E) -> 0 | O5: =_xlfn.XLOOKUP($D5,'Feb 2026'!$D:$D,'Feb 2026'!$E:$E) -> 0 | P5: =_xlfn.XLOOKUP($D5,'Mar 2026'!$D:$D,'Mar 2026'!$E:$E) -> 0 | Q5: =_xlfn.XLOOKUP($D5,'April 2026'!$D:$D,'April 2026'!$E:$E) -> 5 | R5: =_xlfn.XLOOKUP($D5,'May 2026'!$D:$D,'May 2026'!$E:$E) -> 0 | S5: =_xlfn.XLOOKUP($D5,'June 2026'!$D:$D,'June 2026'!$E:$E) -> 0 | T5: =_xlfn.XLOOKUP($D5,'July 2026'!$D:$D,'July 2026'!$E:$E) -> 0 | U5: =_xlfn.XLOOKUP($D5,'Aug 2026'!$D:$D,'Aug 2026'!$E:$E) -> 0 | V5: =_xlfn.XLOOKUP($D5,'Sept 2026'!$D:$D,'Sept 2026'!$E:$E) -> 0 | W5: =_xlfn.XLOOKUP($D5,'Oct 2026'!$D:$D,'Oct 2026'!$E:$E) -> 0 | X5: =_xlfn.XLOOKUP($D5,'Nov 2026'!$D:$D,'Nov 2026'!$E:$E) -> 0 | Y5: =_xlfn.XLOOKUP($D5,'Dec 2026'!$D:$D,'Dec 2026'!$E:$E) -> 0
A6: 3 | B6: LT | C6: Director of Business Services | D6: Al Achy, Wissam | E6: =_xlfn.XLOOKUP(D6,'Contract Entitlement'!$D$4:$D$61,'Contract Entitlement'!$G$4:$G$61) -> 45231 | G6: =_xlfn.XLOOKUP(D6,'Contract Entitlement'!$D$4:$D$61,'Contract Entitlement'!$F$4:$F$61) -> 20 | H6: =IF(YEAR(E6)=2026,IF(DAY(E6)<15,CEILING(G6 * (12 - MONTH(E6) + 1) / 12,1),FLOOR(G6 * (12 - MONTH(E6) + 1) / 12,1)),IF(YEAR(E6)<2026,G6,0)) -> 20 | I6: =SUM(N6:Y6) -> 0 | J6: =COUNTIFS('2026 Time Off Request'!$A$2:$A$822,D6,'2026 Time Off Request'!$E$2:$E$822,"UNPAID") -> 0 | K6: =H6-I6 -> 20 | L6: =K6/G6 -> 1 | N6: =_xlfn.XLOOKUP($D6,'Jan 2026'!$D:$D,'Jan 2026'!$E:$E) -> 0 | O6: =_xlfn.XLOOKUP($D6,'Feb 2026'!$D:$D,'Feb 2026'!$E:$E) -> 0 | P6: =_xlfn.XLOOKUP($D6,'Mar 2026'!$D:$D,'Mar 2026'!$E:$E) -> 0 | Q6: =_xlfn.XLOOKUP($D6,'April 2026'!$D:$D,'April 2026'!$E:$E) -> 0 | R6: =_xlfn.XLOOKUP($D6,'May 2026'!$D:$D,'May 2026'!$E:$E) -> 0 | S6: =_xlfn.XLOOKUP($D6,'June 2026'!$D:$D,'June 2026'!$E:$E) -> 0 | T6: =_xlfn.XLOOKUP($D6,'July 2026'!$D:$D,'July 2026'!$E:$E) -> 0 | U6: =_xlfn.XLOOKUP($D6,'Aug 2026'!$D:$D,'Aug 2026'!$E:$E) -> 0 | V6: =_xlfn.XLOOKUP($D6,'Sept 2026'!$D:$D,'Sept 2026'!$E:$E) -> 0 | W6: =_xlfn.XLOOKUP($D6,'Oct 2026'!$D:$D,'Oct 2026'!$E:$E) -> 0 | X6: =_xlfn.XLOOKUP($D6,'Nov 2026'!$D:$D,'Nov 2026'!$E:$E) -> 0 | Y6: =_xlfn.XLOOKUP($D6,'Dec 2026'!$D:$D,'Dec 2026'!$E:$E) -> 0
A7: 4 | B7: LT | C7: Dentist Relations Manager | D7: Elduweini, Aman | E7: =_xlfn.XLOOKUP(D7,'Contract Entitlement'!$D$4:$D$61,'Contract Entitlement'!$G$4:$G$61) -> 44746 | G7: =_xlfn.XLOOKUP(D7,'Contract Entitlement'!$D$4:$D$61,'Contract Entitlement'!$F$4:$F$61) -> 20 | H7: =IF(YEAR(E7)=2026,IF(DAY(E7)<15,CEILING(G7 * (12 - MONTH(E7) + 1) / 12,1),FLOOR(G7 * (12 - MONTH(E7) + 1) / 12,1)),IF(YEAR(E7)<2026,G7,0)) -> 20 | I7: =SUM(N7:Y7) -> 5 | J7: =COUNTIFS('2026 Time Off Request'!$A$2:$A$822,D7,'2026 Time Off Request'!$E$2:$E$822,"UNPAID") -> 0 | K7: =H7-I7 -> 15 | L7: =K7/G7 -> 0.75 | N7: =_xlfn.XLOOKUP($D7,'Jan 2026'!$D:$D,'Jan 2026'!$E:$E) -> 1 | O7: =_xlfn.XLOOKUP($D7,'Feb 2026'!$D:$D,'Feb 2026'!$E:$E) -> 0 | P7: =_xlfn.XLOOKUP($D7,'Mar 2026'!$D:$D,'Mar 2026'!$E:$E) -> 0 | Q7: =_xlfn.XLOOKUP($D7,'April 2026'!$D:$D,'April 2026'!$E:$E) -> 0 | R7: =_xlfn.XLOOKUP($D7,'May 2026'!$D:$D,'May 2026'!$E:$E) -> 4 | S7: =_xlfn.XLOOKUP($D7,'June 2026'!$D:$D,'June 2026'!$E:$E) -> 0 | T7: =_xlfn.XLOOKUP($D7,'July 2026'!$D:$D,'July 2026'!$E:$E) -> 0 | U7: =_xlfn.XLOOKUP($D7,'Aug 2026'!$D:$D,'Aug 2026'!$E:$E) -> 0 | V7: =_xlfn.XLOOKUP($D7,'Sept 2026'!$D:$D,'Sept 2026'!$E:$E) -> 0 | W7: =_xlfn.XLOOKUP($D7,'Oct 2026'!$D:$D,'Oct 2026'!$E:$E) -> 0 | X7: =_xlfn.XLOOKUP($D7,'Nov 2026'!$D:$D,'Nov 2026'!$E:$E) -> 0 | Y7: =_xlfn.XLOOKUP($D7,'Dec 2026'!$D:$D,'Dec 2026'!$E:$E) -> 0
A8: 5 | B8: LT | C8: Director of IT | D8: Ayoub, Laith | E8: =_xlfn.XLOOKUP(D8,'Contract Entitlement'!$D$4:$D$61,'Contract Entitlement'!$G$4:$G$61) -> 44270 | G8: =_xlfn.XLOOKUP(D8,'Contract Entitlement'!$D$4:$D$61,'Contract Entitlement'!$F$4:$F$61) -> 20 | H8: =IF(YEAR(E8)=2026,IF(DAY(E8)<15,CEILING(G8 * (12 - MONTH(E8) + 1) / 12,1),FLOOR(G8 * (12 - MONTH(E8) + 1) / 12,1)),IF(YEAR(E8)<2026,G8,0)) -> 20 | I8: =SUM(N8:Y8) -> 4 | J8: =COUNTIFS('2026 Time Off Request'!$A$2:$A$822,D8,'2026 Time Off Request'!$E$2:$E$822,"UNPAID") -> 0 | K8: =H8-I8 -> 16 | L8: =K8/G8 -> 0.8 | N8: =_xlfn.XLOOKUP($D8,'Jan 2026'!$D:$D,'Jan 2026'!$E:$E) -> 0 | O8: =_xlfn.XLOOKUP($D8,'Feb 2026'!$D:$D,'Feb 2026'!$E:$E) -> 0 | P8: =_xlfn.XLOOKUP($D8,'Mar 2026'!$D:$D,'Mar 2026'!$E:$E) -> 4 | Q8: =_xlfn.XLOOKUP($D8,'April 2026'!$D:$D,'April 2026'!$E:$E) -> 0 | R8: =_xlfn.XLOOKUP($D8,'May 2026'!$D:$D,'May 2026'!$E:$E) -> 0 | S8: =_xlfn.XLOOKUP($D8,'June 2026'!$D:$D,'June 2026'!$E:$E) -> 0 | T8: =_xlfn.XLOOKUP($D8,'July 2026'!$D:$D,'July 2026'!$E:$E) -> 0 | U8: =_xlfn.XLOOKUP($D8,'Aug 2026'!$D:$D,'Aug 2026'!$E:$E) -> 0 | V8: =_xlfn.XLOOKUP($D8,'Sept 2026'!$D:$D,'Sept 2026'!$E:$E) -> 0 | W8: =_xlfn.XLOOKUP($D8,'Oct 2026'!$D:$D,'Oct 2026'!$E:$E) -> 0 | X8: =_xlfn.XLOOKUP($D8,'Nov 2026'!$D:$D,'Nov 2026'!$E:$E) -> 0 | Y8: =_xlfn.XLOOKUP($D8,'Dec 2026'!$D:$D,'Dec 2026'!$E:$E) -> 0
A9: 7 | B9: RM | C9: Regional Manager | D9: Hellegards, Mandi | E9: =_xlfn.XLOOKUP(D9,'Contract Entitlement'!$D$4:$D$61,'Contract Entitlement'!$G$4:$G$61) -> 42826 | G9: =_xlfn.XLOOKUP(D9,'Contract Entitlement'!$D$4:$D$61,'Contract Entitlement'!$F$4:$F$61) -> 15 | H9: =IF(YEAR(E9)=2026,IF(DAY(E9)<15,CEILING(G9 * (12 - MONTH(E9) + 1) / 12,1),FLOOR(G9 * (12 - MONTH(E9) + 1) / 12,1)),IF(YEAR(E9)<2026,G9,0)) -> 15 | I9: =SUM(N9:Y9) -> 0 | J9: =COUNTIFS('2026 Time Off Request'!$A$2:$A$822,D9,'2026 Time Off Request'!$E$2:$E$822,"UNPAID") -> 0 | K9: =H9-I9 -> 15 | L9: =K9/G9 -> 1 | N9: =_xlfn.XLOOKUP($D9,'Jan 2026'!$D:$D,'Jan 2026'!$E:$E) -> 0 | O9: =_xlfn.XLOOKUP($D9,'Feb 2026'!$D:$D,'Feb 2026'!$E:$E) -> 0 | P9: =_xlfn.XLOOKUP($D9,'Mar 2026'!$D:$D,'Mar 2026'!$E:$E) -> 0 | Q9: =_xlfn.XLOOKUP($D9,'April 2026'!$D:$D,'April 2026'!$E:$E) -> 0 | R9: =_xlfn.XLOOKUP($D9,'May 2026'!$D:$D,'May 2026'!$E:$E) -> 0 | S9: =_xlfn.XLOOKUP($D9,'June 2026'!$D:$D,'June 2026'!$E:$E) -> 0 | T9: =_xlfn.XLOOKUP($D9,'July 2026'!$D:$D,'July 2026'!$E:$E) -> 0 | U9: =_xlfn.XLOOKUP($D9,'Aug 2026'!$D:$D,'Aug 2026'!$E:$E) -> 0 | V9: =_xlfn.XLOOKUP($D9,'Sept 2026'!$D:$D,'Sept 2026'!$E:$E) -> 0 | W9: =_xlfn.XLOOKUP($D9,'Oct 2026'!$D:$D,'Oct 2026'!$E:$E) -> 0 | X9: =_xlfn.XLOOKUP($D9,'Nov 2026'!$D:$D,'Nov 2026'!$E:$E) -> 0 | Y9: =_xlfn.XLOOKUP($D9,'Dec 2026'!$D:$D,'Dec 2026'!$E:$E) -> 0
A10: 8 | B10: RM | C10: Regional Manager | D10: Olberg, Cheryl | E10: =_xlfn.XLOOKUP(D10,'Contract Entitlement'!$D$4:$D$61,'Contract Entitlement'!$G$4:$G$61) -> 38596 | G10: =_xlfn.XLOOKUP(D10,'Contract Entitlement'!$D$4:$D$61,'Contract Entitlement'!$F$4:$F$61) -> 25 | H10: =IF(YEAR(E10)=2026,IF(DAY(E10)<15,CEILING(G10 * (12 - MONTH(E10) + 1) / 12,1),FLOOR(G10 * (12 - MONTH(E10) + 1) / 12,1)),IF(YEAR(E10)<2026,G10,0)) -> 25 | I10: =SUM(N10:Y10) -> 12 | J10: =COUNTIFS('2026 Time Off Request'!$A$2:$A$822,D10,'2026 Time Off Request'!$E$2:$E$822,"UNPAID") -> 0 | K10: =H10-I10 -> 13 | L10: =K10/G10 -> 0.52 | N10: =_xlfn.XLOOKUP($D10,'Jan 2026'!$D:$D,'Jan 2026'!$E:$E) -> 4 | O10: =_xlfn.XLOOKUP($D10,'Feb 2026'!$D:$D,'Feb 2026'!$E:$E) -> 0 | P10: =_xlfn.XLOOKUP($D10,'Mar 2026'!$D:$D,'Mar 2026'!$E:$E) -> 0 | Q10: =_xlfn.XLOOKUP($D10,'April 2026'!$D:$D,'April 2026'!$E:$E) -> 4 | R10: =_xlfn.XLOOKUP($D10,'May 2026'!$D:$D,'May 2026'!$E:$E) -> 4 | S10: =_xlfn.XLOOKUP($D10,'June 2026'!$D:$D,'June 2026'!$E:$E) -> 0 | T10: =_xlfn.XLOOKUP($D10,'July 2026'!$D:$D,'July 2026'!$E:$E) -> 0 | U10: =_xlfn.XLOOKUP($D10,'Aug 2026'!$D:$D,'Aug 2026'!$E:$E) -> 0 | V10: =_xlfn.XLOOKUP($D10,'Sept 2026'!$D:$D,'Sept 2026'!$E:$E) -> 0 | W10: =_xlfn.XLOOKUP($D10,'Oct 2026'!$D:$D,'Oct 2026'!$E:$E) -> 0 | X10: =_xlfn.XLOOKUP($D10,'Nov 2026'!$D:$D,'Nov 2026'!$E:$E) -> 0 | Y10: =_xlfn.XLOOKUP($D10,'Dec 2026'!$D:$D,'Dec 2026'!$E:$E) -> 0
A11: 9 | B11: RM | C11: Regional Manager | D11: Placsko, Jamie | E11: =_xlfn.XLOOKUP(D11,'Contract Entitlement'!$D$4:$D$61,'Contract Entitlement'!$G$4:$G$61) -> 44383 | G11: =_xlfn.XLOOKUP(D11,'Contract Entitlement'!$D$4:$D$61,'Contract Entitlement'!$F$4:$F$61) -> 15 | H11: =IF(YEAR(E11)=2026,IF(DAY(E11)<15,CEILING(G11 * (12 - MONTH(E11) + 1) / 12,1),FLOOR(G11 * (12 - MONTH(E11) + 1) / 12,1)),IF(YEAR(E11)<2026,G11,0)) -> 15 | I11: =SUM(N11:Y11) -> 16 | J11: =COUNTIFS('2026 Time Off Request'!$A$2:$A$822,D11,'2026 Time Off Request'!$E$2:$E$822,"UNPAID") -> 0 | K11: =H11-I11 -> -1 | L11: =K11/G11 -> -0.066666667 | N11: =_xlfn.XLOOKUP($D11,'Jan 2026'!$D:$D,'Jan 2026'!$E:$E) -> 0 | O11: =_xlfn.XLOOKUP($D11,'Feb 2026'!$D:$D,'Feb 2026'!$E:$E) -> 6 | P11: =_xlfn.XLOOKUP($D11,'Mar 2026'!$D:$D,'Mar 2026'!$E:$E) -> 10 | Q11: =_xlfn.XLOOKUP($D11,'April 2026'!$D:$D,'April 2026'!$E:$E) -> 0 | R11: =_xlfn.XLOOKUP($D11,'May 2026'!$D:$D,'May 2026'!$E:$E) -> 0 | S11: =_xlfn.XLOOKUP($D11,'June 2026'!$D:$D,'June 2026'!$E:$E) -> 0 | T11: =_xlfn.XLOOKUP($D11,'July 2026'!$D:$D,'July 2026'!$E:$E) -> 0 | U11: =_xlfn.XLOOKUP($D11,'Aug 2026'!$D:$D,'Aug 2026'!$E:$E) -> 0 | V11: =_xlfn.XLOOKUP($D11,'Sept 2026'!$D:$D,'Sept 2026'!$E:$E) -> 0 | W11: =_xlfn.XLOOKUP($D11,'Oct 2026'!$D:$D,'Oct 2026'!$E:$E) -> 0 | X11: =_xlfn.XLOOKUP($D11,'Nov 2026'!$D:$D,'Nov 2026'!$E:$E) -> 0 | Y11: =_xlfn.XLOOKUP($D11,'Dec 2026'!$D:$D,'Dec 2026'!$E:$E) -> 0
A12: 10 | B12: RM | C12: Regional Manager | D12: Bernard, Jennifer | E12: =_xlfn.XLOOKUP(D12,'Contract Entitlement'!$D$4:$D$61,'Contract Entitlement'!$G$4:$G$61) -> 45789 | G12: =_xlfn.XLOOKUP(D12,'Contract Entitlement'!$D$4:$D$61,'Contract Entitlement'!$F$4:$F$61) -> 15 | H12: =IF(YEAR(E12)=2026,IF(DAY(E12)<15,CEILING(G12 * (12 - MONTH(E12) + 1) / 12,1),FLOOR(G12 * (12 - MONTH(E12) + 1) / 12,1)),IF(YEAR(E12)<2026,G12,0)) -> 15 | I12: =SUM(N12:Y12) -> 0 | J12: =COUNTIFS('2026 Time Off Request'!$A$2:$A$822,D12,'2026 Time Off Request'!$E$2:$E$822,"UNPAID") -> 0 | K12: =H12-I12 -> 15 | L12: =K12/G12 -> 1 | N12: =_xlfn.XLOOKUP($D12,'Jan 2026'!$D:$D,'Jan 2026'!$E:$E) -> 0 | O12: =_xlfn.XLOOKUP($D12,'Feb 2026'!$D:$D,'Feb 2026'!$E:$E) -> 0 | P12: =_xlfn.XLOOKUP($D12,'Mar 2026'!$D:$D,'Mar 2026'!$E:$E) -> 0 | Q12: =_xlfn.XLOOKUP($D12,'April 2026'!$D:$D,'April 2026'!$E:$E) -> 0 | R12: =_xlfn.XLOOKUP($D12,'May 2026'!$D:$D,'May 2026'!$E:$E) -> 0 | S12: =_xlfn.XLOOKUP($D12,'June 2026'!$D:$D,'June 2026'!$E:$E) -> 0 | T12: =_xlfn.XLOOKUP($D12,'July 2026'!$D:$D,'July 2026'!$E:$E) -> 0 | U12: =_xlfn.XLOOKUP($D12,'Aug 2026'!$D:$D,'Aug 2026'!$E:$E) -> 0 | V12: =_xlfn.XLOOKUP($D12,'Sept 2026'!$D:$D,'Sept 2026'!$E:$E) -> 0 | W12: =_xlfn.XLOOKUP($D12,'Oct 2026'!$D:$D,'Oct 2026'!$E:$E) -> 0 | X12: =_xlfn.XLOOKUP($D12,'Nov 2026'!$D:$D,'Nov 2026'!$E:$E) -> 0 | Y12: =_xlfn.XLOOKUP($D12,'Dec 2026'!$D:$D,'Dec 2026'!$E:$E) -> 0
A13: 11 | B13: RM | C13: Regional Manager | D13: Brijlall, Asha Chetna | E13: =_xlfn.XLOOKUP(D13,'Contract Entitlement'!$D$4:$D$61,'Contract Entitlement'!$G$4:$G$61) -> 45880 | G13: =_xlfn.XLOOKUP(D13,'Contract Entitlement'!$D$4:$D$61,'Contract Entitlement'!$F$4:$F$61) -> 15 | H13: =IF(YEAR(E13)=2026,IF(DAY(E13)<15,CEILING(G13 * (12 - MONTH(E13) + 1) / 12,1),FLOOR(G13 * (12 - MONTH(E13) + 1) / 12,1)),IF(YEAR(E13)<2026,G13,0)) -> 15 | I13: =SUM(N13:Y13) -> 1 | J13: =COUNTIFS('2026 Time Off Request'!$A$2:$A$822,D13,'2026 Time Off Request'!$E$2:$E$822,"UNPAID") -> 0 | K13: =H13-I13 -> 14 | L13: =K13/G13 -> 0.93333333 | N13: =_xlfn.XLOOKUP($D13,'Jan 2026'!$D:$D,'Jan 2026'!$E:$E) -> 1 | O13: =_xlfn.XLOOKUP($D13,'Feb 2026'!$D:$D,'Feb 2026'!$E:$E) -> 0 | P13: =_xlfn.XLOOKUP($D13,'Mar 2026'!$D:$D,'Mar 2026'!$E:$E) -> 0 | Q13: =_xlfn.XLOOKUP($D13,'April 2026'!$D:$D,'April 2026'!$E:$E) -> 0 | R13: =_xlfn.XLOOKUP($D13,'May 2026'!$D:$D,'May 2026'!$E:$E) -> 0 | S13: =_xlfn.XLOOKUP($D13,'June 2026'!$D:$D,'June 2026'!$E:$E) -> 0 | T13: =_xlfn.XLOOKUP($D13,'July 2026'!$D:$D,'July 2026'!$E:$E) -> 0 | U13: =_xlfn.XLOOKUP($D13,'Aug 2026'!$D:$D,'Aug 2026'!$E:$E) -> 0 | V13: =_xlfn.XLOOKUP($D13,'Sept 2026'!$D:$D,'Sept 2026'!$E:$E) -> 0 | W13: =_xlfn.XLOOKUP($D13,'Oct 2026'!$D:$D,'Oct 2026'!$E:$E) -> 0 | X13: =_xlfn.XLOOKUP($D13,'Nov 2026'!$D:$D,'Nov 2026'!$E:$E) -> 0 | Y13: =_xlfn.XLOOKUP($D13,'Dec 2026'!$D:$D,'Dec 2026'!$E:$E) -> 0
A14: 12 | B14: RM | C14: Regional Manager | D14: Harlow, Mark | E14: =_xlfn.XLOOKUP(D14,'Contract Entitlement'!$D$4:$D$61,'Contract Entitlement'!$G$4:$G$61) -> 44811 | G14: =_xlfn.XLOOKUP(D14,'Contract Entitlement'!$D$4:$D$61,'Contract Entitlement'!$F$4:$F$61) -> 15 | H14: =IF(YEAR(E14)=2026,IF(DAY(E14)<15,CEILING(G14 * (12 - MONTH(E14) + 1) / 12,1),FLOOR(G14 * (12 - MONTH(E14) + 1) / 12,1)),IF(YEAR(E14)<2026,G14,0)) -> 15 | I14: =SUM(N14:Y14) -> 6 | J14: =COUNTIFS('2026 Time Off Request'!$A$2:$A$822,D14,'2026 Time Off Request'!$E$2:$E$822,"UNPAID") -> 0 | K14: =H14-I14 -> 9 | L14: =K14/G14 -> 0.6 | N14: =_xlfn.XLOOKUP($D14,'Jan 2026'!$D:$D,'Jan 2026'!$E:$E) -> 1 | O14: =_xlfn.XLOOKUP($D14,'Feb 2026'!$D:$D,'Feb 2026'!$E:$E) -> 2 | P14: =_xlfn.XLOOKUP($D14,'Mar 2026'!$D:$D,'Mar 2026'!$E:$E) -> 1 | Q14: =_xlfn.XLOOKUP($D14,'April 2026'!$D:$D,'April 2026'!$E:$E) -> 0 | R14: =_xlfn.XLOOKUP($D14,'May 2026'!$D:$D,'May 2026'!$E:$E) -> 0 | S14: =_xlfn.XLOOKUP($D14,'June 2026'!$D:$D,'June 2026'!$E:$E) -> 0 | T14: =_xlfn.XLOOKUP($D14,'July 2026'!$D:$D,'July 2026'!$E:$E) -> 0 | U14: =_xlfn.XLOOKUP($D14,'Aug 2026'!$D:$D,'Aug 2026'!$E:$E) -> 2 | V14: =_xlfn.XLOOKUP($D14,'Sept 2026'!$D:$D,'Sept 2026'!$E:$E) -> 0 | W14: =_xlfn.XLOOKUP($D14,'Oct 2026'!$D:$D,'Oct 2026'!$E:$E) -> 0 | X14: =_xlfn.XLOOKUP($D14,'Nov 2026'!$D:$D,'Nov 2026'!$E:$E) -> 0 | Y14: =_xlfn.XLOOKUP($D14,'Dec 2026'!$D:$D,'Dec 2026'!$E:$E) -> 0
A15: 13 | B15: RM | C15: Regional Manager | D15: Ciccone, Shelley | E15: =_xlfn.XLOOKUP(D15,'Contract Entitlement'!$D$4:$D$61,'Contract Entitlement'!$G$4:$G$61) -> 45964 | G15: =_xlfn.XLOOKUP(D15,'Contract Entitlement'!$D$4:$D$61,'Contract Entitlement'!$F$4:$F$61) -> 15 | H15: =IF(YEAR(E15)=2026,IF(DAY(E15)<15,CEILING(G15 * (12 - MONTH(E15) + 1) / 12,1),FLOOR(G15 * (12 - MONTH(E15) + 1) / 12,1)),IF(YEAR(E15)<2026,G15,0)) -> 15 | I15: =SUM(N15:Y15) -> 0 | J15: =COUNTIFS('2026 Time Off Request'!$A$2:$A$822,D15,'2026 Time Off Request'!$E$2:$E$822,"UNPAID") -> 0 | K15: =H15-I15 -> 15 | L15: =K15/G15 -> 1 | N15: =_xlfn.XLOOKUP($D15,'Jan 2026'!$D:$D,'Jan 2026'!$E:$E) -> 0 | O15: =_xlfn.XLOOKUP($D15,'Feb 2026'!$D:$D,'Feb 2026'!$E:$E) -> 0 | P15: =_xlfn.XLOOKUP($D15,'Mar 2026'!$D:$D,'Mar 2026'!$E:$E) -> 0 | Q15: =_xlfn.XLOOKUP($D15,'April 2026'!$D:$D,'April 2026'!$E:$E) -> 0 | R15: =_xlfn.XLOOKUP($D15,'May 2026'!$D:$D,'May 2026'!$E:$E) -> 0 | S15: =_xlfn.XLOOKUP($D15,'June 2026'!$D:$D,'June 2026'!$E:$E) -> 0 | T15: =_xlfn.XLOOKUP($D15,'July 2026'!$D:$D,'July 2026'!$E:$E) -> 0 | U15: =_xlfn.XLOOKUP($D15,'Aug 2026'!$D:$D,'Aug 2026'!$E:$E) -> 0 | V15: =_xlfn.XLOOKUP($D15,'Sept 2026'!$D:$D,'Sept 2026'!$E:$E) -> 0 | W15: =_xlfn.XLOOKUP($D15,'Oct 2026'!$D:$D,'Oct 2026'!$E:$E) -> 0 | X15: =_xlfn.XLOOKUP($D15,'Nov 2026'!$D:$D,'Nov 2026'!$E:$E) -> 0 | Y15: =_xlfn.XLOOKUP($D15,'Dec 2026'!$D:$D,'Dec 2026'!$E:$E) -> 0
A16: 14 | B16: ST | C16: Regional Manager | D16: Habash, Odeh Justin | E16: =_xlfn.XLOOKUP(D16,'Contract Entitlement'!$D$4:$D$61,'Contract Entitlement'!$G$4:$G$61) -> 45826 | G16: =_xlfn.XLOOKUP(D16,'Contract Entitlement'!$D$4:$D$61,'Contract Entitlement'!$F$4:$F$61) -> 10 | H16: =IF(YEAR(E16)=2026,IF(DAY(E16)<15,CEILING(G16 * (12 - MONTH(E16) + 1) / 12,1),FLOOR(G16 * (12 - MONTH(E16) + 1) / 12,1)),IF(YEAR(E16)<2026,G16,0)) -> 10 | I16: =SUM(N16:Y16) -> 0 | J16: =COUNTIFS('2026 Time Off Request'!$A$2:$A$822,D16,'2026 Time Off Request'!$E$2:$E$822,"UNPAID") -> 0 | K16: =H16-I16 -> 10 | L16: =K16/G16 -> 1 | N16: =_xlfn.XLOOKUP($D16,'Jan 2026'!$D:$D,'Jan 2026'!$E:$E) -> 0 | O16: =_xlfn.XLOOKUP($D16,'Feb 2026'!$D:$D,'Feb 2026'!$E:$E) -> 0 | P16: =_xlfn.XLOOKUP($D16,'Mar 2026'!$D:$D,'Mar 2026'!$E:$E) -> 0 | Q16: =_xlfn.XLOOKUP($D16,'April 2026'!$D:$D,'April 2026'!$E:$E) -> 0 | R16: =_xlfn.XLOOKUP($D16,'May 2026'!$D:$D,'May 2026'!$E:$E) -> 0 | S16: =_xlfn.XLOOKUP($D16,'June 2026'!$D:$D,'June 2026'!$E:$E) -> 0 | T16: =_xlfn.XLOOKUP($D16,'July 2026'!$D:$D,'July 2026'!$E:$E) -> 0 | U16: =_xlfn.XLOOKUP($D16,'Aug 2026'!$D:$D,'Aug 2026'!$E:$E) -> 0 | V16: =_xlfn.XLOOKUP($D16,'Sept 2026'!$D:$D,'Sept 2026'!$E:$E) -> 0 | W16: =_xlfn.XLOOKUP($D16,'Oct 2026'!$D:$D,'Oct 2026'!$E:$E) -> 0 | X16: =_xlfn.XLOOKUP($D16,'Nov 2026'!$D:$D,'Nov 2026'!$E:$E) -> 0 | Y16: =_xlfn.XLOOKUP($D16,'Dec 2026'!$D:$D,'Dec 2026'!$E:$E) -> 0
... A19: 17 | B19: ST | C19: Talent Acquisition Specialist | D19: Zymeri, Rineta | E19: =_xlfn.XLOOKUP(D19,'Contract Entitlement'!$D$4:$D$61,'Contract Entitlement'!$G$4:$G$61) -> 45882 | G19: =_xlfn.XLOOKUP(D19,'Contract Entitlement'!$D$4:$D$61,'Contract Entitlement'!$F$4:$F$61) -> 15 | H19: =IF(YEAR(E19)=2026,IF(DAY(E19)<15,CEILING(G19 * (12 - MONTH(E19) + 1) / 12,1),FLOOR(G19 * (12 - MONTH(E19) + 1) / 12,1)),IF(YEAR(E19)<2026,G19,0)) -> 15 | I19: =SUM(N19:Y19) -> 0 | J19: =COUNTIFS('2026 Time Off Request'!$A$2:$A$822,D19,'2026 Time Off Request'!$E$2:$E$822,"UNPAID") -> 0 | K19: =H19-I19 -> 15 | L19: =K19/G19 -> 1 | N19: =_xlfn.XLOOKUP($D19,'Jan 2026'!$D:$D,'Jan 2026'!$E:$E) -> 0 | O19: =_xlfn.XLOOKUP($D19,'Feb 2026'!$D:$D,'Feb 2026'!$E:$E) -> 0 | P19: =_xlfn.XLOOKUP($D19,'Mar 2026'!$D:$D,'Mar 2026'!$E:$E) -> 0 | Q19: =_xlfn.XLOOKUP($D19,'April 2026'!$D:$D,'April 2026'!$E:$E) -> 0 | R19: =_xlfn.XLOOKUP($D19,'May 2026'!$D:$D,'May 2026'!$E:$E) -> 0 | S19: =_xlfn.XLOOKUP($D19,'June 2026'!$D:$D,'June 2026'!$E:$E) -> 0 | T19: =_xlfn.XLOOKUP($D19,'July 2026'!$D:$D,'July 2026'!$E:$E) -> 0 | U19: =_xlfn.XLOOKUP($D19,'Aug 2026'!$D:$D,'Aug 2026'!$E:$E) -> 0 | V19: =_xlfn.XLOOKUP($D19,'Sept 2026'!$D:$D,'Sept 2026'!$E:$E) -> 0 | W19: =_xlfn.XLOOKUP($D19,'Oct 2026'!$D:$D,'Oct 2026'!$E:$E) -> 0 | X19: =_xlfn.XLOOKUP($D19,'Nov 2026'!$D:$D,'Nov 2026'!$E:$E) -> 0 | Y19: =_xlfn.XLOOKUP($D19,'Dec 2026'!$D:$D,'Dec 2026'!$E:$E) -> 0
B20: ST | C20: Talent Acquisition Specialist | D20: Kaiser, Erika | E20: =_xlfn.XLOOKUP(D20,'Contract Entitlement'!$D$4:$D$61,'Contract Entitlement'!$G$4:$G$61) -> 46076 | G20: =_xlfn.XLOOKUP(D20,'Contract Entitlement'!$D$4:$D$61,'Contract Entitlement'!$F$4:$F$61) -> 15 | H20: =IF(YEAR(E20)=2026,IF(DAY(E20)<15,CEILING(G20 * (12 - MONTH(E20) + 1) / 12,1),FLOOR(G20 * (12 - MONTH(E20) + 1) / 12,1)),IF(YEAR(E20)<2026,G20,0)) -> 13 | I20: =SUM(O20:Y20) -> 0 | J20: =COUNTIFS('2026 Time Off Request'!$A$2:$A$822,D20,'2026 Time Off Request'!$E$2:$E$822,"UNPAID") -> 0 | K20: =H20-I20 -> 13 | L20: =K20/G20 -> 0.86666667 | N20: =_xlfn.XLOOKUP($D20,'Jan 2026'!$D:$D,'Jan 2026'!$E:$E) -> #N/A | O20: =_xlfn.XLOOKUP($D20,'Feb 2026'!$D:$D,'Feb 2026'!$E:$E) -> 0 | P20: =_xlfn.XLOOKUP($D20,'Mar 2026'!$D:$D,'Mar 2026'!$E:$E) -> 0 | Q20: =_xlfn.XLOOKUP($D20,'April 2026'!$D:$D,'April 2026'!$E:$E) -> 0 | R20: =_xlfn.XLOOKUP($D20,'May 2026'!$D:$D,'May 2026'!$E:$E) -> 0 | S20: =_xlfn.XLOOKUP($D20,'June 2026'!$D:$D,'June 2026'!$E:$E) -> 0 | T20: =_xlfn.XLOOKUP($D20,'July 2026'!$D:$D,'July 2026'!$E:$E) -> 0 | U20: =_xlfn.XLOOKUP($D20,'Aug 2026'!$D:$D,'Aug 2026'!$E:$E) -> 0 | V20: =_xlfn.XLOOKUP($D20,'Sept 2026'!$D:$D,'Sept 2026'!$E:$E) -> 0 | W20: =_xlfn.XLOOKUP($D20,'Oct 2026'!$D:$D,'Oct 2026'!$E:$E) -> 0 | X20: =_xlfn.XLOOKUP($D20,'Nov 2026'!$D:$D,'Nov 2026'!$E:$E) -> 0 | Y20: =_xlfn.XLOOKUP($D20,'Dec 2026'!$D:$D,'Dec 2026'!$E:$E) -> 0
A21: 18 | B21: ST | C21: Project Manager | D21: Rana, Surya | E21: =_xlfn.XLOOKUP(D21,'Contract Entitlement'!$D$4:$D$61,'Contract Entitlement'!$G$4:$G$61) -> 45538 | G21: =_xlfn.XLOOKUP(D21,'Contract Entitlement'!$D$4:$D$61,'Contract Entitlement'!$F$4:$F$61) -> 15 | H21: =IF(YEAR(E21)=2026,IF(DAY(E21)<15,CEILING(G21 * (12 - MONTH(E21) + 1) / 12,1),FLOOR(G21 * (12 - MONTH(E21) + 1) / 12,1)),IF(YEAR(E21)<2026,G21,0)) -> 15 | I21: =SUM(N21:Y21) -> 5 | J21: =COUNTIFS('2026 Time Off Request'!$A$2:$A$822,D21,'2026 Time Off Request'!$E$2:$E$822,"UNPAID") -> 0 | K21: =H21-I21 -> 10 | L21: =K21/G21 -> 0.66666667 | N21: =_xlfn.XLOOKUP($D21,'Jan 2026'!$D:$D,'Jan 2026'!$E:$E) -> 3 | O21: =_xlfn.XLOOKUP($D21,'Feb 2026'!$D:$D,'Feb 2026'!$E:$E) -> 2 | P21: =_xlfn.XLOOKUP($D21,'Mar 2026'!$D:$D,'Mar 2026'!$E:$E) -> 0 | Q21: =_xlfn.XLOOKUP($D21,'April 2026'!$D:$D,'April 2026'!$E:$E) -> 0 | R21: =_xlfn.XLOOKUP($D21,'May 2026'!$D:$D,'May 2026'!$E:$E) -> 0 | S21: =_xlfn.XLOOKUP($D21,'June 2026'!$D:$D,'June 2026'!$E:$E) -> 0 | T21: =_xlfn.XLOOKUP($D21,'July 2026'!$D:$D,'July 2026'!$E:$E) -> 0 | U21: =_xlfn.XLOOKUP($D21,'Aug 2026'!$D:$D,'Aug 2026'!$E:$E) -> 0 | V21: =_xlfn.XLOOKUP($D21,'Sept 2026'!$D:$D,'Sept 2026'!$E:$E) -> 0 | W21: =_xlfn.XLOOKUP($D21,'Oct 2026'!$D:$D,'Oct 2026'!$E:$E) -> 0 | X21: =_xlfn.XLOOKUP($D21,'Nov 2026'!$D:$D,'Nov 2026'!$E:$E) -> 0 | Y21: =_xlfn.XLOOKUP($D21,'Dec 2026'!$D:$D,'Dec 2026'!$E:$E) -> 0
B22: ST | C22: Project Manager | D22: Srikanth, Asha | E22: =_xlfn.XLOOKUP(D22,'Contract Entitlement'!$D$4:$D$61,'Contract Entitlement'!$G$4:$G$61) -> 46076 | G22: =_xlfn.XLOOKUP(D22,'Contract Entitlement'!$D$4:$D$61,'Contract Entitlement'!$F$4:$F$61) -> 10 | H22: =IF(YEAR(E22)=2026,IF(DAY(E22)<15,CEILING(G22 * (12 - MONTH(E22) + 1) / 12,1),FLOOR(G22 * (12 - MONTH(E22) + 1) / 12,1)),IF(YEAR(E22)<2026,G22,0)) -> 9 | I22: =SUM(O22:Y22) -> 0 | J22: =COUNTIFS('2026 Time Off Request'!$A$2:$A$822,D22,'2026 Time Off Request'!$E$2:$E$822,"UNPAID") -> 0 | K22: =H22-I22 -> 9 | L22: =K22/G22 -> 0.9 | N22: =_xlfn.XLOOKUP($D22,'Jan 2026'!$D:$D,'Jan 2026'!$E:$E) -> #N/A | O22: =_xlfn.XLOOKUP($D22,'Feb 2026'!$D:$D,'Feb 2026'!$E:$E) -> 0 | P22: =_xlfn.XLOOKUP($D22,'Mar 2026'!$D:$D,'Mar 2026'!$E:$E) -> 0 | Q22: =_xlfn.XLOOKUP($D22,'April 2026'!$D:$D,'April 2026'!$E:$E) -> 0 | R22: =_xlfn.XLOOKUP($D22,'May 2026'!$D:$D,'May 2026'!$E:$E) -> 0 | S22: =_xlfn.XLOOKUP($D22,'June 2026'!$D:$D,'June 2026'!$E:$E) -> 0 | T22: =_xlfn.XLOOKUP($D22,'July 2026'!$D:$D,'July 2026'!$E:$E) -> 0 | U22: =_xlfn.XLOOKUP($D22,'Aug 2026'!$D:$D,'Aug 2026'!$E:$E) -> 0 | V22: =_xlfn.XLOOKUP($D22,'Sept 2026'!$D:$D,'Sept 2026'!$E:$E) -> 0 | W22: =_xlfn.XLOOKUP($D22,'Oct 2026'!$D:$D,'Oct 2026'!$E:$E) -> 0 | X22: =_xlfn.XLOOKUP($D22,'Nov 2026'!$D:$D,'Nov 2026'!$E:$E) -> 0 | Y22: =_xlfn.XLOOKUP($D22,'Dec 2026'!$D:$D,'Dec 2026'!$E:$E) -> 0
A23: 19 | B23: ST | C23: IT Support Specialist | D23: Armstrong, David | E23: =_xlfn.XLOOKUP(D23,'Contract Entitlement'!$D$4:$D$61,'Contract Entitlement'!$G$4:$G$61) -> 44522 | G23: =_xlfn.XLOOKUP(D23,'Contract Entitlement'!$D$4:$D$61,'Contract Entitlement'!$F$4:$F$61) -> 15 | H23: =IF(YEAR(E23)=2026,IF(DAY(E23)<15,CEILING(G23 * (12 - MONTH(E23) + 1) / 12,1),FLOOR(G23 * (12 - MONTH(E23) + 1) / 12,1)),IF(YEAR(E23)<2026,G23,0)) -> 15 | I23: =SUM(N23:Y23) -> 1 | J23: =COUNTIFS('2026 Time Off Request'!$A$2:$A$822,D23,'2026 Time Off Request'!$E$2:$E$822,"UNPAID") -> 0 | K23: =H23-I23 -> 14 | L23: =K23/G23 -> 0.93333333 | N23: =_xlfn.XLOOKUP($D23,'Jan 2026'!$D:$D,'Jan 2026'!$E:$E) -> 0 | O23: =_xlfn.XLOOKUP($D23,'Feb 2026'!$D:$D,'Feb 2026'!$E:$E) -> 0 | P23: =_xlfn.XLOOKUP($D23,'Mar 2026'!$D:$D,'Mar 2026'!$E:$E) -> 1 | Q23: =_xlfn.XLOOKUP($D23,'April 2026'!$D:$D,'April 2026'!$E:$E) -> 0 | R23: =_xlfn.XLOOKUP($D23,'May 2026'!$D:$D,'May 2026'!$E:$E) -> 0 | S23: =_xlfn.XLOOKUP($D23,'June 2026'!$D:$D,'June 2026'!$E:$E) -> 0 | T23: =_xlfn.XLOOKUP($D23,'July 2026'!$D:$D,'July 2026'!$E:$E) -> 0 | U23: =_xlfn.XLOOKUP($D23,'Aug 2026'!$D:$D,'Aug 2026'!$E:$E) -> 0 | V23: =_xlfn.XLOOKUP($D23,'Sept 2026'!$D:$D,'Sept 2026'!$E:$E) -> 0 | W23: =_xlfn.XLOOKUP($D23,'Oct 2026'!$D:$D,'Oct 2026'!$E:$E) -> 0 | X23: =_xlfn.XLOOKUP($D23,'Nov 2026'!$D:$D,'Nov 2026'!$E:$E) -> 0 | Y23: =_xlfn.XLOOKUP($D23,'Dec 2026'!$D:$D,'Dec 2026'!$E:$E) -> 0
A24: 20 | B24: ST | C24: Solutions Architect | D24: Puri, Deepesh | E24: =_xlfn.XLOOKUP(D24,'Contract Entitlement'!$D$4:$D$61,'Contract Entitlement'!$G$4:$G$61) -> 45831 | G24: =_xlfn.XLOOKUP(D24,'Contract Entitlement'!$D$4:$D$61,'Contract Entitlement'!$F$4:$F$61) -> 10 | H24: =IF(YEAR(E24)=2026,IF(DAY(E24)<15,CEILING(G24 * (12 - MONTH(E24) + 1) / 12,1),FLOOR(G24 * (12 - MONTH(E24) + 1) / 12,1)),IF(YEAR(E24)<2026,G24,0)) -> 10 | I24: =SUM(N24:Y24) -> 0 | J24: =COUNTIFS('2026 Time Off Request'!$A$2:$A$822,D24,'2026 Time Off Request'!$E$2:$E$822,"UNPAID") -> 0 | K24: =H24-I24 -> 10 | L24: =K24/G24 -> 1 | N24: =_xlfn.XLOOKUP($D24,'Jan 2026'!$D:$D,'Jan 2026'!$E:$E) -> 0 | O24: =_xlfn.XLOOKUP($D24,'Feb 2026'!$D:$D,'Feb 2026'!$E:$E) -> 0 | P24: =_xlfn.XLOOKUP($D24,'Mar 2026'!$D:$D,'Mar 2026'!$E:$E) -> 0 | Q24: =_xlfn.XLOOKUP($D24,'April 2026'!$D:$D,'April 2026'!$E:$E) -> 0 | R24: =_xlfn.XLOOKUP($D24,'May 2026'!$D:$D,'May 2026'!$E:$E) -> 0 | S24: =_xlfn.XLOOKUP($D24,'June 2026'!$D:$D,'June 2026'!$E:$E) -> 0 | T24: =_xlfn.XLOOKUP($D24,'July 2026'!$D:$D,'July 2026'!$E:$E) -> 0 | U24: =_xlfn.XLOOKUP($D24,'Aug 2026'!$D:$D,'Aug 2026'!$E:$E) -> 0 | V24: =_xlfn.XLOOKUP($D24,'Sept 2026'!$D:$D,'Sept 2026'!$E:$E) -> 0 | W24: =_xlfn.XLOOKUP($D24,'Oct 2026'!$D:$D,'Oct 2026'!$E:$E) -> 0 | X24: =_xlfn.XLOOKUP($D24,'Nov 2026'!$D:$D,'Nov 2026'!$E:$E) -> 0 | Y24: =_xlfn.XLOOKUP($D24,'Dec 2026'!$D:$D,'Dec 2026'!$E:$E) -> 0
B25: ST | C25: Data Analyst | D25: Lopez, David | E25: =_xlfn.XLOOKUP(D25,'Contract Entitlement'!$D$4:$D$61,'Contract Entitlement'!$G$4:$G$61) -> 46078 | G25: =_xlfn.XLOOKUP(D25,'Contract Entitlement'!$D$4:$D$61,'Contract Entitlement'!$F$4:$F$61) -> 10 | H25: =IF(YEAR(E25)=2026,IF(DAY(E25)<15,CEILING(G25 * (12 - MONTH(E25) + 1) / 12,1),FLOOR(G25 * (12 - MONTH(E25) + 1) / 12,1)),IF(YEAR(E25)<2026,G25,0)) -> 9 | I25: =SUM(O25:Y25) -> 0 | J25: =COUNTIFS('2026 Time Off Request'!$A$2:$A$822,D25,'2026 Time Off Request'!$E$2:$E$822,"UNPAID") -> 0 | K25: =H25-I25 -> 9 | L25: =K25/G25 -> 0.9 | N25: =_xlfn.XLOOKUP($D25,'Jan 2026'!$D:$D,'Jan 2026'!$E:$E) -> #N/A | O25: =_xlfn.XLOOKUP($D25,'Feb 2026'!$D:$D,'Feb 2026'!$E:$E) -> 0 | P25: =_xlfn.XLOOKUP($D25,'Mar 2026'!$D:$D,'Mar 2026'!$E:$E) -> 0 | Q25: =_xlfn.XLOOKUP($D25,'April 2026'!$D:$D,'April 2026'!$E:$E) -> 0 | R25: =_xlfn.XLOOKUP($D25,'May 2026'!$D:$D,'May 2026'!$E:$E) -> 0 | S25: =_xlfn.XLOOKUP($D25,'June 2026'!$D:$D,'June 2026'!$E:$E) -> 0 | T25: =_xlfn.XLOOKUP($D25,'July 2026'!$D:$D,'July 2026'!$E:$E) -> 0 | U25: =_xlfn.XLOOKUP($D25,'Aug 2026'!$D:$D,'Aug 2026'!$E:$E) -> 0 | V25: =_xlfn.XLOOKUP($D25,'Sept 2026'!$D:$D,'Sept 2026'!$E:$E) -> 0 | W25: =_xlfn.XLOOKUP($D25,'Oct 2026'!$D:$D,'Oct 2026'!$E:$E) -> 0 | X25: =_xlfn.XLOOKUP($D25,'Nov 2026'!$D:$D,'Nov 2026'!$E:$E) -> 0 | Y25: =_xlfn.XLOOKUP($D25,'Dec 2026'!$D:$D,'Dec 2026'!$E:$E) -> 0
A26: 21 | B26: ST Mgr | C26: Digital Marketing Manager | D26: Abi Khalil, Marwan | E26: =_xlfn.XLOOKUP(D26,'Contract Entitlement'!$D$4:$D$61,'Contract Entitlement'!$G$4:$G$61) -> 45152 | G26: =_xlfn.XLOOKUP(D26,'Contract Entitlement'!$D$4:$D$61,'Contract Entitlement'!$F$4:$F$61) -> 20 | H26: =IF(YEAR(E26)=2026,IF(DAY(E26)<15,CEILING(G26 * (12 - MONTH(E26) + 1) / 12,1),FLOOR(G26 * (12 - MONTH(E26) + 1) / 12,1)),IF(YEAR(E26)<2026,G26,0)) -> 20 | I26: =SUM(N26:Y26) -> 1 | J26: =COUNTIFS('2026 Time Off Request'!$A$2:$A$822,D26,'2026 Time Off Request'!$E$2:$E$822,"UNPAID") -> 0 | K26: =H26-I26 -> 19 | L26: =K26/G26 -> 0.95 | N26: =_xlfn.XLOOKUP($D26,'Jan 2026'!$D:$D,'Jan 2026'!$E:$E) -> 0 | O26: =_xlfn.XLOOKUP($D26,'Feb 2026'!$D:$D,'Feb 2026'!$E:$E) -> 0 | P26: =_xlfn.XLOOKUP($D26,'Mar 2026'!$D:$D,'Mar 2026'!$E:$E) -> 1 | Q26: =_xlfn.XLOOKUP($D26,'April 2026'!$D:$D,'April 2026'!$E:$E) -> 0 | R26: =_xlfn.XLOOKUP($D26,'May 2026'!$D:$D,'May 2026'!$E:$E) -> 0 | S26: =_xlfn.XLOOKUP($D26,'June 2026'!$D:$D,'June 2026'!$E:$E) -> 0 | T26: =_xlfn.XLOOKUP($D26,'July 2026'!$D:$D,'July 2026'!$E:$E) -> 0 | U26: =_xlfn.XLOOKUP($D26,'Aug 2026'!$D:$D,'Aug 2026'!$E:$E) -> 0 | V26: =_xlfn.XLOOKUP($D26,'Sept 2026'!$D:$D,'Sept 2026'!$E:$E) -> 0 | W26: =_xlfn.XLOOKUP($D26,'Oct 2026'!$D:$D,'Oct 2026'!$E:$E) -> 0 | X26: =_xlfn.XLOOKUP($D26,'Nov 2026'!$D:$D,'Nov 2026'!$E:$E) -> 0 | Y26: =_xlfn.XLOOKUP($D26,'Dec 2026'!$D:$D,'Dec 2026'!$E:$E) -> 0
A27: 22 | B27: ST Mgr | C27: Sr. Design Manager | D27: Ford, Claire | E27: =_xlfn.XLOOKUP(D27,'Contract Entitlement'!$D$4:$D$61,'Contract Entitlement'!$G$4:$G$61) -> 45964 | G27: =_xlfn.XLOOKUP(D27,'Contract Entitlement'!$D$4:$D$61,'Contract Entitlement'!$F$4:$F$61) -> 15 | H27: =IF(YEAR(E27)=2026,IF(DAY(E27)<15,CEILING(G27 * (12 - MONTH(E27) + 1) / 12,1),FLOOR(G27 * (12 - MONTH(E27) + 1) / 12,1)),IF(YEAR(E27)<2026,G27,0)) -> 15 | I27: =SUM(N27:Y27) -> 2 | J27: =COUNTIFS('2026 Time Off Request'!$A$2:$A$822,D27,'2026 Time Off Request'!$E$2:$E$822,"UNPAID") -> 0 | K27: =H27-I27 -> 13 | L27: =K27/G27 -> 0.86666667 | N27: =_xlfn.XLOOKUP($D27,'Jan 2026'!$D:$D,'Jan 2026'!$E:$E) -> 0 | O27: =_xlfn.XLOOKUP($D27,'Feb 2026'!$D:$D,'Feb 2026'!$E:$E) -> 1 | P27: =_xlfn.XLOOKUP($D27,'Mar 2026'!$D:$D,'Mar 2026'!$E:$E) -> 1 | Q27: =_xlfn.XLOOKUP($D27,'April 2026'!$D:$D,'April 2026'!$E:$E) -> 0 | R27: =_xlfn.XLOOKUP($D27,'May 2026'!$D:$D,'May 2026'!$E:$E) -> 0 | S27: =_xlfn.XLOOKUP($D27,'June 2026'!$D:$D,'June 2026'!$E:$E) -> 0 | T27: =_xlfn.XLOOKUP($D27,'July 2026'!$D:$D,'July 2026'!$E:$E) -> 0 | U27: =_xlfn.XLOOKUP($D27,'Aug 2026'!$D:$D,'Aug 2026'!$E:$E) -> 0 | V27: =_xlfn.XLOOKUP($D27,'Sept 2026'!$D:$D,'Sept 2026'!$E:$E) -> 0 | W27: =_xlfn.XLOOKUP($D27,'Oct 2026'!$D:$D,'Oct 2026'!$E:$E) -> 0 | X27: =_xlfn.XLOOKUP($D27,'Nov 2026'!$D:$D,'Nov 2026'!$E:$E) -> 0 | Y27: =_xlfn.XLOOKUP($D27,'Dec 2026'!$D:$D,'Dec 2026'!$E:$E) -> 0
A28: 23 | B28: ST | C28: Event Planner | D28: Clark, Celestyna Ruth | E28: =_xlfn.XLOOKUP(D28,'Contract Entitlement'!$D$4:$D$61,'Contract Entitlement'!$G$4:$G$61) -> 45712 | G28: =_xlfn.XLOOKUP(D28,'Contract Entitlement'!$D$4:$D$61,'Contract Entitlement'!$F$4:$F$61) -> 10 | H28: =IF(YEAR(E28)=2026,IF(DAY(E28)<15,CEILING(G28 * (12 - MONTH(E28) + 1) / 12,1),FLOOR(G28 * (12 - MONTH(E28) + 1) / 12,1)),IF(YEAR(E28)<2026,G28,0)) -> 10 | I28: =SUM(N28:Y28) -> 4 | J28: =COUNTIFS('2026 Time Off Request'!$A$2:$A$822,D28,'2026 Time Off Request'!$E$2:$E$822,"UNPAID") -> 0 | K28: =H28-I28 -> 6 | L28: =K28/G28 -> 0.6 | N28: =_xlfn.XLOOKUP($D28,'Jan 2026'!$D:$D,'Jan 2026'!$E:$E) -> 3 | O28: =_xlfn.XLOOKUP($D28,'Feb 2026'!$D:$D,'Feb 2026'!$E:$E) -> 0 | P28: =_xlfn.XLOOKUP($D28,'Mar 2026'!$D:$D,'Mar 2026'!$E:$E) -> 1 | Q28: =_xlfn.XLOOKUP($D28,'April 2026'!$D:$D,'April 2026'!$E:$E) -> 0 | R28: =_xlfn.XLOOKUP($D28,'May 2026'!$D:$D,'May 2026'!$E:$E) -> 0 | S28: =_xlfn.XLOOKUP($D28,'June 2026'!$D:$D,'June 2026'!$E:$E) -> 0 | T28: =_xlfn.XLOOKUP($D28,'July 2026'!$D:$D,'July 2026'!$E:$E) -> 0 | U28: =_xlfn.XLOOKUP($D28,'Aug 2026'!$D:$D,'Aug 2026'!$E:$E) -> 0 | V28: =_xlfn.XLOOKUP($D28,'Sept 2026'!$D:$D,'Sept 2026'!$E:$E) -> 0 | W28: =_xlfn.XLOOKUP($D28,'Oct 2026'!$D:$D,'Oct 2026'!$E:$E) -> 0 | X28: =_xlfn.XLOOKUP($D28,'Nov 2026'!$D:$D,'Nov 2026'!$E:$E) -> 0 | Y28: =_xlfn.XLOOKUP($D28,'Dec 2026'!$D:$D,'Dec 2026'!$E:$E) -> 0
A29: 24 | B29: ST | C29: Creative Designer | D29: Kedia, Vidhisha | E29: =_xlfn.XLOOKUP(D29,'Contract Entitlement'!$D$4:$D$61,'Contract Entitlement'!$G$4:$G$61) -> 45264 | G29: =_xlfn.XLOOKUP(D29,'Contract Entitlement'!$D$4:$D$61,'Contract Entitlement'!$F$4:$F$61) -> 10 | H29: =IF(YEAR(E29)=2026,IF(DAY(E29)<15,CEILING(G29 * (12 - MONTH(E29) + 1) / 12,1),FLOOR(G29 * (12 - MONTH(E29) + 1) / 12,1)),IF(YEAR(E29)<2026,G29,0)) -> 10 | I29: =SUM(N29:Y29) -> 0 | J29: =COUNTIFS('2026 Time Off Request'!$A$2:$A$822,D29,'2026 Time Off Request'!$E$2:$E$822,"UNPAID") -> 0 | K29: =H29-I29 -> 10 | L29: =K29/G29 -> 1 | N29: =_xlfn.XLOOKUP($D29,'Jan 2026'!$D:$D,'Jan 2026'!$E:$E) -> 0 | O29: =_xlfn.XLOOKUP($D29,'Feb 2026'!$D:$D,'Feb 2026'!$E:$E) -> 0 | P29: =_xlfn.XLOOKUP($D29,'Mar 2026'!$D:$D,'Mar 2026'!$E:$E) -> 0 | Q29: =_xlfn.XLOOKUP($D29,'April 2026'!$D:$D,'April 2026'!$E:$E) -> 0 | R29: =_xlfn.XLOOKUP($D29,'May 2026'!$D:$D,'May 2026'!$E:$E) -> 0 | S29: =_xlfn.XLOOKUP($D29,'June 2026'!$D:$D,'June 2026'!$E:$E) -> 0 | T29: =_xlfn.XLOOKUP($D29,'July 2026'!$D:$D,'July 2026'!$E:$E) -> 0 | U29: =_xlfn.XLOOKUP($D29,'Aug 2026'!$D:$D,'Aug 2026'!$E:$E) -> 0 | V29: =_xlfn.XLOOKUP($D29,'Sept 2026'!$D:$D,'Sept 2026'!$E:$E) -> 0 | W29: =_xlfn.XLOOKUP($D29,'Oct 2026'!$D:$D,'Oct 2026'!$E:$E) -> 0 | X29: =_xlfn.XLOOKUP($D29,'Nov 2026'!$D:$D,'Nov 2026'!$E:$E) -> 0 | Y29: =_xlfn.XLOOKUP($D29,'Dec 2026'!$D:$D,'Dec 2026'!$E:$E) -> 0
A30: 25 | B30: ST | C30: Creative Designer | D30: Kocznur, Jesse | E30: =_xlfn.XLOOKUP(D30,'Contract Entitlement'!$D$4:$D$61,'Contract Entitlement'!$G$4:$G$61) -> 45275 | G30: =_xlfn.XLOOKUP(D30,'Contract Entitlement'!$D$4:$D$61,'Contract Entitlement'!$F$4:$F$61) -> 10 | H30: =IF(YEAR(E30)=2026,IF(DAY(E30)<15,CEILING(G30 * (12 - MONTH(E30) + 1) / 12,1),FLOOR(G30 * (12 - MONTH(E30) + 1) / 12,1)),IF(YEAR(E30)<2026,G30,0)) -> 10 | I30: =SUM(N30:Y30) -> 5 | J30: =COUNTIFS('2026 Time Off Request'!$A$2:$A$822,D30,'2026 Time Off Request'!$E$2:$E$822,"UNPAID") -> 0 | K30: =H30-I30 -> 5 | L30: =K30/G30 -> 0.5 | N30: =_xlfn.XLOOKUP($D30,'Jan 2026'!$D:$D,'Jan 2026'!$E:$E) -> 0 | O30: =_xlfn.XLOOKUP($D30,'Feb 2026'!$D:$D,'Feb 2026'!$E:$E) -> 1 | P30: =_xlfn.XLOOKUP($D30,'Mar 2026'!$D:$D,'Mar 2026'!$E:$E) -> 0 | Q30: =_xlfn.XLOOKUP($D30,'April 2026'!$D:$D,'April 2026'!$E:$E) -> 0 | R30: =_xlfn.XLOOKUP($D30,'May 2026'!$D:$D,'May 2026'!$E:$E) -> 0 | S30: =_xlfn.XLOOKUP($D30,'June 2026'!$D:$D,'June 2026'!$E:$E) -> 0 | T30: =_xlfn.XLOOKUP($D30,'July 2026'!$D:$D,'July 2026'!$E:$E) -> 4 | U30: =_xlfn.XLOOKUP($D30,'Aug 2026'!$D:$D,'Aug 2026'!$E:$E) -> 0 | V30: =_xlfn.XLOOKUP($D30,'Sept 2026'!$D:$D,'Sept 2026'!$E:$E) -> 0 | W30: =_xlfn.XLOOKUP($D30,'Oct 2026'!$D:$D,'Oct 2026'!$E:$E) -> 0 | X30: =_xlfn.XLOOKUP($D30,'Nov 2026'!$D:$D,'Nov 2026'!$E:$E) -> 0 | Y30: =_xlfn.XLOOKUP($D30,'Dec 2026'!$D:$D,'Dec 2026'!$E:$E) -> 0
A31: 26 | B31: ST | C31: Motion Designer | D31: John, Jonathan | E31: =_xlfn.XLOOKUP(D31,'Contract Entitlement'!$D$4:$D$61,'Contract Entitlement'!$G$4:$G$61) -> 46050 | G31: =_xlfn.XLOOKUP(D31,'Contract Entitlement'!$D$4:$D$61,'Contract Entitlement'!$F$4:$F$61) -> 10 | H31: =IF(YEAR(E31)=2026,IF(DAY(E31)<15,CEILING(G31 * (12 - MONTH(E31) + 1) / 12,1),FLOOR(G31 * (12 - MONTH(E31) + 1) / 12,1)),IF(YEAR(E31)<2026,G31,0)) -> 10 | I31: =SUM(N31:Y31) -> 0 | J31: =COUNTIFS('2026 Time Off Request'!$A$2:$A$822,D31,'2026 Time Off Request'!$E$2:$E$822,"UNPAID") -> 0 | K31: =H31-I31 -> 10 | L31: =K31/G31 -> 1 | N31: =_xlfn.XLOOKUP($D31,'Jan 2026'!$D:$D,'Jan 2026'!$E:$E) -> 0 | O31: =_xlfn.XLOOKUP($D31,'Feb 2026'!$D:$D,'Feb 2026'!$E:$E) -> 0 | P31: =_xlfn.XLOOKUP($D31,'Mar 2026'!$D:$D,'Mar 2026'!$E:$E) -> 0 | Q31: =_xlfn.XLOOKUP($D31,'April 2026'!$D:$D,'April 2026'!$E:$E) -> 0 | R31: =_xlfn.XLOOKUP($D31,'May 2026'!$D:$D,'May 2026'!$E:$E) -> 0 | S31: =_xlfn.XLOOKUP($D31,'June 2026'!$D:$D,'June 2026'!$E:$E) -> 0 | T31: =_xlfn.XLOOKUP($D31,'July 2026'!$D:$D,'July 2026'!$E:$E) -> 0 | U31: =_xlfn.XLOOKUP($D31,'Aug 2026'!$D:$D,'Aug 2026'!$E:$E) -> 0 | V31: =_xlfn.XLOOKUP($D31,'Sept 2026'!$D:$D,'Sept 2026'!$E:$E) -> 0 | W31: =_xlfn.XLOOKUP($D31,'Oct 2026'!$D:$D,'Oct 2026'!$E:$E) -> 0 | X31: =_xlfn.XLOOKUP($D31,'Nov 2026'!$D:$D,'Nov 2026'!$E:$E) -> 0 | Y31: =_xlfn.XLOOKUP($D31,'Dec 2026'!$D:$D,'Dec 2026'!$E:$E) -> 0
A32: 27 | B32: ST Mgr | C32: Call Center Manager | D32: Jones, Brandie Gayle | E32: =_xlfn.XLOOKUP(D32,'Contract Entitlement'!$D$4:$D$61,'Contract Entitlement'!$G$4:$G$61) -> 45817 | G32: =_xlfn.XLOOKUP(D32,'Contract Entitlement'!$D$4:$D$61,'Contract Entitlement'!$F$4:$F$61) -> 15 | H32: =IF(YEAR(E32)=2026,IF(DAY(E32)<15,CEILING(G32 * (12 - MONTH(E32) + 1) / 12,1),FLOOR(G32 * (12 - MONTH(E32) + 1) / 12,1)),IF(YEAR(E32)<2026,G32,0)) -> 15 | I32: =SUM(N32:Y32) -> 5 | J32: =COUNTIFS('2026 Time Off Request'!$A$2:$A$822,D32,'2026 Time Off Request'!$E$2:$E$822,"UNPAID") -> 0 | K32: =H32-I32 -> 10 | L32: =K32/G32 -> 0.66666667 | N32: =_xlfn.XLOOKUP($D32,'Jan 2026'!$D:$D,'Jan 2026'!$E:$E) -> 0 | O32: =_xlfn.XLOOKUP($D32,'Feb 2026'!$D:$D,'Feb 2026'!$E:$E) -> 5 | P32: =_xlfn.XLOOKUP($D32,'Mar 2026'!$D:$D,'Mar 2026'!$E:$E) -> 0 | Q32: =_xlfn.XLOOKUP($D32,'April 2026'!$D:$D,'April 2026'!$E:$E) -> 0 | R32: =_xlfn.XLOOKUP($D32,'May 2026'!$D:$D,'May 2026'!$E:$E) -> 0 | S32: =_xlfn.XLOOKUP($D32,'June 2026'!$D:$D,'June 2026'!$E:$E) -> 0 | T32: =_xlfn.XLOOKUP($D32,'July 2026'!$D:$D,'July 2026'!$E:$E) -> 0 | U32: =_xlfn.XLOOKUP($D32,'Aug 2026'!$D:$D,'Aug 2026'!$E:$E) -> 0 | V32: =_xlfn.XLOOKUP($D32,'Sept 2026'!$D:$D,'Sept 2026'!$E:$E) -> 0 | W32: =_xlfn.XLOOKUP($D32,'Oct 2026'!$D:$D,'Oct 2026'!$E:$E) -> 0 | X32: =_xlfn.XLOOKUP($D32,'Nov 2026'!$D:$D,'Nov 2026'!$E:$E) -> 0 | Y32: =_xlfn.XLOOKUP($D32,'Dec 2026'!$D:$D,'Dec 2026'!$E:$E) -> 0
A33: 28 | B33: ST | C33: Call Center Rep | D33: Black, Marijna Alida | E33: =_xlfn.XLOOKUP(D33,'Contract Entitlement'!$D$4:$D$61,'Contract Entitlement'!$G$4:$G$61) -> 45833 | G33: =_xlfn.XLOOKUP(D33,'Contract Entitlement'!$D$4:$D$61,'Contract Entitlement'!$F$4:$F$61) -> 10 | H33: =IF(YEAR(E33)=2026,IF(DAY(E33)<15,CEILING(G33 * (12 - MONTH(E33) + 1) / 12,1),FLOOR(G33 * (12 - MONTH(E33) + 1) / 12,1)),IF(YEAR(E33)<2026,G33,0)) -> 10 | I33: =SUM(N33:Y33) -> 5 | J33: =COUNTIFS('2026 Time Off Request'!$A$2:$A$822,D33,'2026 Time Off Request'!$E$2:$E$822,"UNPAID") -> 5 | K33: =H33-I33 -> 5 | L33: =K33/G33 -> 0.5 | N33: =_xlfn.XLOOKUP($D33,'Jan 2026'!$D:$D,'Jan 2026'!$E:$E) -> 0 | O33: =_xlfn.XLOOKUP($D33,'Feb 2026'!$D:$D,'Feb 2026'!$E:$E) -> 0 | P33: =_xlfn.XLOOKUP($D33,'Mar 2026'!$D:$D,'Mar 2026'!$E:$E) -> 0 | Q33: =_xlfn.XLOOKUP($D33,'April 2026'!$D:$D,'April 2026'!$E:$E) -> 0 | R33: =_xlfn.XLOOKUP($D33,'May 2026'!$D:$D,'May 2026'!$E:$E) -> 0 | S33: =_xlfn.XLOOKUP($D33,'June 2026'!$D:$D,'June 2026'!$E:$E) -> 5 | T33: =_xlfn.XLOOKUP($D33,'July 2026'!$D:$D,'July 2026'!$E:$E) -> 0 | U33: =_xlfn.XLOOKUP($D33,'Aug 2026'!$D:$D,'Aug 2026'!$E:$E) -> 0 | V33: =_xlfn.XLOOKUP($D33,'Sept 2026'!$D:$D,'Sept 2026'!$E:$E) -> 0 | W33: =_xlfn.XLOOKUP($D33,'Oct 2026'!$D:$D,'Oct 2026'!$E:$E) -> 0 | X33: =_xlfn.XLOOKUP($D33,'Nov 2026'!$D:$D,'Nov 2026'!$E:$E) -> 0 | Y33: =_xlfn.XLOOKUP($D33,'Dec 2026'!$D:$D,'Dec 2026'!$E:$E) -> 0
A34: 29 | B34: ST | C34: Call Center Rep | D34: Pelius, Jacqulene | E34: =_xlfn.XLOOKUP(D34,'Contract Entitlement'!$D$4:$D$61,'Contract Entitlement'!$G$4:$G$61) -> 45855 | G34: =_xlfn.XLOOKUP(D34,'Contract Entitlement'!$D$4:$D$61,'Contract Entitlement'!$F$4:$F$61) -> 10 | H34: =IF(YEAR(E34)=2026,IF(DAY(E34)<15,CEILING(G34 * (12 - MONTH(E34) + 1) / 12,1),FLOOR(G34 * (12 - MONTH(E34) + 1) / 12,1)),IF(YEAR(E34)<2026,G34,0)) -> 10 | I34: =SUM(N34:Y34) -> 8 | J34: =COUNTIFS('2026 Time Off Request'!$A$2:$A$822,D34,'2026 Time Off Request'!$E$2:$E$822,"UNPAID") -> 8 | K34: =H34-I34 -> 2 | L34: =K34/G34 -> 0.2 | N34: =_xlfn.XLOOKUP($D34,'Jan 2026'!$D:$D,'Jan 2026'!$E:$E) -> 8 | O34: =_xlfn.XLOOKUP($D34,'Feb 2026'!$D:$D,'Feb 2026'!$E:$E) -> 0 | P34: =_xlfn.XLOOKUP($D34,'Mar 2026'!$D:$D,'Mar 2026'!$E:$E) -> 0 | Q34: =_xlfn.XLOOKUP($D34,'April 2026'!$D:$D,'April 2026'!$E:$E) -> 0 | R34: =_xlfn.XLOOKUP($D34,'May 2026'!$D:$D,'May 2026'!$E:$E) -> 0 | S34: =_xlfn.XLOOKUP($D34,'June 2026'!$D:$D,'June 2026'!$E:$E) -> 0 | T34: =_xlfn.XLOOKUP($D34,'July 2026'!$D:$D,'July 2026'!$E:$E) -> 0 | U34: =_xlfn.XLOOKUP($D34,'Aug 2026'!$D:$D,'Aug 2026'!$E:$E) -> 0 | V34: =_xlfn.XLOOKUP($D34,'Sept 2026'!$D:$D,'Sept 2026'!$E:$E) -> 0 | W34: =_xlfn.XLOOKUP($D34,'Oct 2026'!$D:$D,'Oct 2026'!$E:$E) -> 0 | X34: =_xlfn.XLOOKUP($D34,'Nov 2026'!$D:$D,'Nov 2026'!$E:$E) -> 0 | Y34: =_xlfn.XLOOKUP($D34,'Dec 2026'!$D:$D,'Dec 2026'!$E:$E) -> 0
A35: 30 | B35: ST | C35: Call Center Rep | D35: Milankovic, Tatjana | E35: =_xlfn.XLOOKUP(D35,'Contract Entitlement'!$D$4:$D$61,'Contract Entitlement'!$G$4:$G$61) -> 45413 | G35: =_xlfn.XLOOKUP(D35,'Contract Entitlement'!$D$4:$D$61,'Contract Entitlement'!$F$4:$F$61) -> 10 | H35: =IF(YEAR(E35)=2026,IF(DAY(E35)<15,CEILING(G35 * (12 - MONTH(E35) + 1) / 12,1),FLOOR(G35 * (12 - MONTH(E35) + 1) / 12,1)),IF(YEAR(E35)<2026,G35,0)) -> 10 | I35: =SUM(N35:Y35) -> 5 | J35: =COUNTIFS('2026 Time Off Request'!$A$2:$A$822,D35,'2026 Time Off Request'!$E$2:$E$822,"UNPAID") -> 0 | K35: =H35-I35 -> 5 | L35: =K35/G35 -> 0.5 | N35: =_xlfn.XLOOKUP($D35,'Jan 2026'!$D:$D,'Jan 2026'!$E:$E) -> 0 | O35: =_xlfn.XLOOKUP($D35,'Feb 2026'!$D:$D,'Feb 2026'!$E:$E) -> 0 | P35: =_xlfn.XLOOKUP($D35,'Mar 2026'!$D:$D,'Mar 2026'!$E:$E) -> 5 | Q35: =_xlfn.XLOOKUP($D35,'April 2026'!$D:$D,'April 2026'!$E:$E) -> 0 | R35: =_xlfn.XLOOKUP($D35,'May 2026'!$D:$D,'May 2026'!$E:$E) -> 0 | S35: =_xlfn.XLOOKUP($D35,'June 2026'!$D:$D,'June 2026'!$E:$E) -> 0 | T35: =_xlfn.XLOOKUP($D35,'July 2026'!$D:$D,'July 2026'!$E:$E) -> 0 | U35: =_xlfn.XLOOKUP($D35,'Aug 2026'!$D:$D,'Aug 2026'!$E:$E) -> 0 | V35: =_xlfn.XLOOKUP($D35,'Sept 2026'!$D:$D,'Sept 2026'!$E:$E) -> 0 | W35: =_xlfn.XLOOKUP($D35,'Oct 2026'!$D:$D,'Oct 2026'!$E:$E) -> 0 | X35: =_xlfn.XLOOKUP($D35,'Nov 2026'!$D:$D,'Nov 2026'!$E:$E) -> 0 | Y35: =_xlfn.XLOOKUP($D35,'Dec 2026'!$D:$D,'Dec 2026'!$E:$E) -> 0
A36: 31 | B36: ST Mgr | C36: Payroll Manager | D36: Ammari, Waleed | E36: =_xlfn.XLOOKUP(D36,'Contract Entitlement'!$D$4:$D$61,'Contract Entitlement'!$G$4:$G$61) -> 42795 | G36: =_xlfn.XLOOKUP(D36,'Contract Entitlement'!$D$4:$D$61,'Contract Entitlement'!$F$4:$F$61) -> 20 | H36: =IF(YEAR(E36)=2026,IF(DAY(E36)<15,CEILING(G36 * (12 - MONTH(E36) + 1) / 12,1),FLOOR(G36 * (12 - MONTH(E36) + 1) / 12,1)),IF(YEAR(E36)<2026,G36,0)) -> 20 | I36: =SUM(N36:Y36) -> 0 | J36: =COUNTIFS('2026 Time Off Request'!$A$2:$A$822,D36,'2026 Time Off Request'!$E$2:$E$822,"UNPAID") -> 0 | K36: =H36-I36 -> 20 | L36: =K36/G36 -> 1 | N36: =_xlfn.XLOOKUP($D36,'Jan 2026'!$D:$D,'Jan 2026'!$E:$E) -> 0 | O36: =_xlfn.XLOOKUP($D36,'Feb 2026'!$D:$D,'Feb 2026'!$E:$E) -> 0 | P36: =_xlfn.XLOOKUP($D36,'Mar 2026'!$D:$D,'Mar 2026'!$E:$E) -> 0 | Q36: =_xlfn.XLOOKUP($D36,'April 2026'!$D:$D,'April 2026'!$E:$E) -> 0 | R36: =_xlfn.XLOOKUP($D36,'May 2026'!$D:$D,'May 2026'!$E:$E) -> 0 | S36: =_xlfn.XLOOKUP($D36,'June 2026'!$D:$D,'June 2026'!$E:$E) -> 0 | T36: =_xlfn.XLOOKUP($D36,'July 2026'!$D:$D,'July 2026'!$E:$E) -> 0 | U36: =_xlfn.XLOOKUP($D36,'Aug 2026'!$D:$D,'Aug 2026'!$E:$E) -> 0 | V36: =_xlfn.XLOOKUP($D36,'Sept 2026'!$D:$D,'Sept 2026'!$E:$E) -> 0 | W36: =_xlfn.XLOOKUP($D36,'Oct 2026'!$D:$D,'Oct 2026'!$E:$E) -> 0 | X36: =_xlfn.XLOOKUP($D36,'Nov 2026'!$D:$D,'Nov 2026'!$E:$E) -> 0 | Y36: =_xlfn.XLOOKUP($D36,'Dec 2026'!$D:$D,'Dec 2026'!$E:$E) -> 0
A37: 32 | B37: ST | C37: Payroll Admin | D37: Gonzalez Garcia, Yamila | E37: =_xlfn.XLOOKUP(D37,'Contract Entitlement'!$D$4:$D$61,'Contract Entitlement'!$G$4:$G$61) -> 44963 | G37: =_xlfn.XLOOKUP(D37,'Contract Entitlement'!$D$4:$D$61,'Contract Entitlement'!$F$4:$F$61) -> 15 | H37: =IF(YEAR(E37)=2026,IF(DAY(E37)<15,CEILING(G37 * (12 - MONTH(E37) + 1) / 12,1),FLOOR(G37 * (12 - MONTH(E37) + 1) / 12,1)),IF(YEAR(E37)<2026,G37,0)) -> 15 | I37: =SUM(N37:Y37) -> 0 | J37: =COUNTIFS('2026 Time Off Request'!$A$2:$A$822,D37,'2026 Time Off Request'!$E$2:$E$822,"UNPAID") -> 0 | K37: =H37-I37 -> 15 | L37: =K37/G37 -> 1 | N37: =_xlfn.XLOOKUP($D37,'Jan 2026'!$D:$D,'Jan 2026'!$E:$E) -> 0 | O37: =_xlfn.XLOOKUP($D37,'Feb 2026'!$D:$D,'Feb 2026'!$E:$E) -> 0 | P37: =_xlfn.XLOOKUP($D37,'Mar 2026'!$D:$D,'Mar 2026'!$E:$E) -> 0 | Q37: =_xlfn.XLOOKUP($D37,'April 2026'!$D:$D,'April 2026'!$E:$E) -> 0 | R37: =_xlfn.XLOOKUP($D37,'May 2026'!$D:$D,'May 2026'!$E:$E) -> 0 | S37: =_xlfn.XLOOKUP($D37,'June 2026'!$D:$D,'June 2026'!$E:$E) -> 0 | T37: =_xlfn.XLOOKUP($D37,'July 2026'!$D:$D,'July 2026'!$E:$E) -> 0 | U37: =_xlfn.XLOOKUP($D37,'Aug 2026'!$D:$D,'Aug 2026'!$E:$E) -> 0 | V37: =_xlfn.XLOOKUP($D37,'Sept 2026'!$D:$D,'Sept 2026'!$E:$E) -> 0 | W37: =_xlfn.XLOOKUP($D37,'Oct 2026'!$D:$D,'Oct 2026'!$E:$E) -> 0 | X37: =_xlfn.XLOOKUP($D37,'Nov 2026'!$D:$D,'Nov 2026'!$E:$E) -> 0 | Y37: =_xlfn.XLOOKUP($D37,'Dec 2026'!$D:$D,'Dec 2026'!$E:$E) -> 0
... A41: 36 | B41: ST | C41: Accounts Payable Admin | D41: Guirguis, George | E41: =_xlfn.XLOOKUP(D41,'Contract Entitlement'!$D$4:$D$61,'Contract Entitlement'!$G$4:$G$61) -> 44956 | G41: =_xlfn.XLOOKUP(D41,'Contract Entitlement'!$D$4:$D$61,'Contract Entitlement'!$F$4:$F$61) -> 15 | H41: =IF(YEAR(E41)=2026,IF(DAY(E41)<15,CEILING(G41 * (12 - MONTH(E41) + 1) / 12,1),FLOOR(G41 * (12 - MONTH(E41) + 1) / 12,1)),IF(YEAR(E41)<2026,G41,0)) -> 15 | I41: =SUM(N41:Y41) -> 0 | J41: =COUNTIFS('2026 Time Off Request'!$A$2:$A$822,D41,'2026 Time Off Request'!$E$2:$E$822,"UNPAID") -> 0 | K41: =H41-I41 -> 15 | L41: =K41/G41 -> 1 | N41: =_xlfn.XLOOKUP($D41,'Jan 2026'!$D:$D,'Jan 2026'!$E:$E) -> 0 | O41: =_xlfn.XLOOKUP($D41,'Feb 2026'!$D:$D,'Feb 2026'!$E:$E) -> 0 | P41: =_xlfn.XLOOKUP($D41,'Mar 2026'!$D:$D,'Mar 2026'!$E:$E) -> 0 | Q41: =_xlfn.XLOOKUP($D41,'April 2026'!$D:$D,'April 2026'!$E:$E) -> 0 | R41: =_xlfn.XLOOKUP($D41,'May 2026'!$D:$D,'May 2026'!$E:$E) -> 0 | S41: =_xlfn.XLOOKUP($D41,'June 2026'!$D:$D,'June 2026'!$E:$E) -> 0 | T41: =_xlfn.XLOOKUP($D41,'July 2026'!$D:$D,'July 2026'!$E:$E) -> 0 | U41: =_xlfn.XLOOKUP($D41,'Aug 2026'!$D:$D,'Aug 2026'!$E:$E) -> 0 | V41: =_xlfn.XLOOKUP($D41,'Sept 2026'!$D:$D,'Sept 2026'!$E:$E) -> 0 | W41: =_xlfn.XLOOKUP($D41,'Oct 2026'!$D:$D,'Oct 2026'!$E:$E) -> 0 | X41: =_xlfn.XLOOKUP($D41,'Nov 2026'!$D:$D,'Nov 2026'!$E:$E) -> 0 | Y41: =_xlfn.XLOOKUP($D41,'Dec 2026'!$D:$D,'Dec 2026'!$E:$E) -> 0
A43: =+COUNT(A4:A41) -> 35 | C43: TOTAL | G43: =+SUM(G4:G41) -> 570 | H43: =+SUM(H4:H41) -> 566 | I43: =+SUM(I4:I41) -> 99 | J43: =+SUM(J4:J41) -> 13 | K43: =+SUM(K4:K41) -> 467 | L43: =K43/G43 -> 0.81929825 | N43: {=SUM(IFERROR(N4:N41,0))} -> 28 | O43: {=SUM(IFERROR(O4:O41,0))} -> 17 | P43: {=SUM(IFERROR(P4:P41,0))} -> 26 | Q43: {=SUM(IFERROR(Q4:Q41,0))} -> 9 | R43: {=SUM(IFERROR(R4:R41,0))} -> 8 | S43: {=SUM(IFERROR(S4:S41,0))} -> 5 | T43: {=SUM(IFERROR(T4:T41,0))} -> 4 | U43: {=SUM(IFERROR(U4:U41,0))} -> 2 | ... Y43: {=SUM(IFERROR(Y4:Y41,0))} -> 0

Sheet 2025 Monthly Vacation
N1: 1 | O1: 2 | P1: 3 | Q1: 4 | R1: 5 | S1: 6 | T1: 7 | U1: 8 | V1: 9 | W1: 10 | X1: 11 | Y1: 12
B2: Employee Info | G2: 2025 Vacation | N2: 2025 Days Taken Off by Month
B3: Dept | C3: Job Title | D3: Name | E3: Start date | G3: Vacation Days | H3: Pro Rated Days | I3: Days Taken | J3: Unpaid Days Taken | K3: Days Remaining | L3: % Remaining | N3: January | O3: February | P3: March | Q3: April | R3: May | S3: June | T3: July | U3: August | V3: September | W3: October | X3: November | Y3: December
B4: ST | C4: Accountant | D4: Ranasinghe, Praveen | E4: =_xlfn.XLOOKUP(D4,'Contract Entitlement'!$D$4:$D$61,'Contract Entitlement'!$G$4:$G$61) -> 44963 | G4: =_xlfn.XLOOKUP(D4,'Contract Entitlement'!$D$4:$D$61,'Contract Entitlement'!$F$4:$F$61) -> 10 | H4: =IF(YEAR(E4)=2025,IF(DAY(E4)<15,CEILING(G4 * (12 - MONTH(E4) + 1) / 12,1),FLOOR(G4 * (12 - MONTH(E4) + 1) / 12,1)),IF(YEAR(E4)<2025,G4,0)) -> 10 | I4: =SUM(N4:Y4) -> 11 | J4: =COUNTIFS('2025 Time Off Request'!$A$2:$A$422,D4,'2025 Time Off Request'!$E$2:$E$422,"UNPAID") -> 0 | K4: =H4-I4 -> -1 | L4: =K4/G4 -> -0.1 | N4: =COUNTIFS('2025 Time Off Request'!$N$2:$N$422,N$1,'2025 Time Off Request'!$A$2:$A$422,$D4) -> 0 | O4: =COUNTIFS('2025 Time Off Request'!$N$2:$N$422,O$1,'2025 Time Off Request'!$A$2:$A$422,$D4) -> 3 | P4: =COUNTIFS('2025 Time Off Request'!$N$2:$N$422,P$1,'2025 Time Off Request'!$A$2:$A$422,$D4) -> 0 | Q4: =COUNTIFS('2025 Time Off Request'!$N$2:$N$422,Q$1,'2025 Time Off Request'!$A$2:$A$422,$D4) -> 0 | R4: =COUNTIFS('2025 Time Off Request'!$N$2:$N$422,R$1,'2025 Time Off Request'!$A$2:$A$422,$D4) -> 4 | S4: =COUNTIFS('2025 Time Off Request'!$N$2:$N$422,S$1,'2025 Time Off Request'!$A$2:$A$422,$D4) -> 2 | T4: =COUNTIFS('2025 Time Off Request'!$N$2:$N$422,T$1,'2025 Time Off Request'!$A$2:$A$422,$D4) -> 0 | U4: =COUNTIFS('2025 Time Off Request'!$N$2:$N$422,U$1,'2025 Time Off Request'!$A$2:$A$422,$D4) -> 0 | ... Y4: =COUNTIFS('2025 Time Off Request'!$N$2:$N$422,Y$1,'2025 Time Off Request'!$A$2:$A$422,$D4) -> 0
B5: ST | C5: Accounts Payable Admin | D5: Brennan, Cheri | E5: =_xlfn.XLOOKUP(D5,'Contract Entitlement'!$D$4:$D$61,'Contract Entitlement'!$G$4:$G$61) -> 44587 | G5: =_xlfn.XLOOKUP(D5,'Contract Entitlement'!$D$4:$D$61,'Contract Entitlement'!$F$4:$F$61) -> 15 | H5: =IF(YEAR(E5)=2025,IF(DAY(E5)<15,CEILING(G5 * (12 - MONTH(E5) + 1) / 12,1),FLOOR(G5 * (12 - MONTH(E5) + 1) / 12,1)),IF(YEAR(E5)<2025,G5,0)) -> 15 | I5: =SUM(N5:Y5) -> 14 | J5: =COUNTIFS('2025 Time Off Request'!$A$2:$A$422,D5,'2025 Time Off Request'!$E$2:$E$422,"UNPAID") -> 0 | K5: =H5-I5 -> 1 | L5: =K5/G5 -> 0.066666667 | N5: =COUNTIFS('2025 Time Off Request'!$N$2:$N$422,N$1,'2025 Time Off Request'!$A$2:$A$422,$D5) -> 7 | O5: =COUNTIFS('2025 Time Off Request'!$N$2:$N$422,O$1,'2025 Time Off Request'!$A$2:$A$422,$D5) -> 0 | P5: =COUNTIFS('2025 Time Off Request'!$N$2:$N$422,P$1,'2025 Time Off Request'!$A$2:$A$422,$D5) -> 0 | Q5: =COUNTIFS('2025 Time Off Request'!$N$2:$N$422,Q$1,'2025 Time Off Request'!$A$2:$A$422,$D5) -> 0 | R5: =COUNTIFS('2025 Time Off Request'!$N$2:$N$422,R$1,'2025 Time Off Request'!$A$2:$A$422,$D5) -> 2 | S5: =COUNTIFS('2025 Time Off Request'!$N$2:$N$422,S$1,'2025 Time Off Request'!$A$2:$A$422,$D5) -> 3 | T5: =COUNTIFS('2025 Time Off Request'!$N$2:$N$422,T$1,'2025 Time Off Request'!$A$2:$A$422,$D5) -> 1 | U5: =COUNTIFS('2025 Time Off Request'!$N$2:$N$422,U$1,'2025 Time Off Request'!$A$2:$A$422,$D5) -> 0 | ... Y5: =COUNTIFS('2025 Time Off Request'!$N$2:$N$422,Y$1,'2025 Time Off Request'!$A$2:$A$422,$D5) -> 0
B6: ST | C6: Accounts Payable Admin | D6: Guirguis, George | E6: =_xlfn.XLOOKUP(D6,'Contract Entitlement'!$D$4:$D$61,'Contract Entitlement'!$G$4:$G$61) -> 44956 | G6: =_xlfn.XLOOKUP(D6,'Contract Entitlement'!$D$4:$D$61,'Contract Entitlement'!$F$4:$F$61) -> 15 | H6: =IF(YEAR(E6)=2025,IF(DAY(E6)<15,CEILING(G6 * (12 - MONTH(E6) + 1) / 12,1),FLOOR(G6 * (12 - MONTH(E6) + 1) / 12,1)),IF(YEAR(E6)<2025,G6,0)) -> 15 | I6: =SUM(N6:Y6) -> 2 | J6: =COUNTIFS('2025 Time Off Request'!$A$2:$A$422,D6,'2025 Time Off Request'!$E$2:$E$422,"UNPAID") -> 0 | K6: =H6-I6 -> 13 | L6: =K6/G6 -> 0.86666667 | N6: =COUNTIFS('2025 Time Off Request'!$N$2:$N$422,N$1,'2025 Time Off Request'!$A$2:$A$422,$D6) -> 0 | O6: =COUNTIFS('2025 Time Off Request'!$N$2:$N$422,O$1,'2025 Time Off Request'!$A$2:$A$422,$D6) -> 0 | P6: =COUNTIFS('2025 Time Off Request'!$N$2:$N$422,P$1,'2025 Time Off Request'!$A$2:$A$422,$D6) -> 0 | Q6: =COUNTIFS('2025 Time Off Request'!$N$2:$N$422,Q$1,'2025 Time Off Request'!$A$2:$A$422,$D6) -> 0 | R6: =COUNTIFS('2025 Time Off Request'!$N$2:$N$422,R$1,'2025 Time Off Request'!$A$2:$A$422,$D6) -> 0 | S6: =COUNTIFS('2025 Time Off Request'!$N$2:$N$422,S$1,'2025 Time Off Request'!$A$2:$A$422,$D6) -> 0 | T6: =COUNTIFS('2025 Time Off Request'!$N$2:$N$422,T$1,'2025 Time Off Request'!$A$2:$A$422,$D6) -> 0 | U6: =COUNTIFS('2025 Time Off Request'!$N$2:$N$422,U$1,'2025 Time Off Request'!$A$2:$A$422,$D6) -> 0 | ... Y6: =COUNTIFS('2025 Time Off Request'!$N$2:$N$422,Y$1,'2025 Time Off Request'!$A$2:$A$422,$D6) -> 0
B7: ST Mgr | C7: Call Center Manager | D7: Jones, Brandie Gayle | E7: =_xlfn.XLOOKUP(D7,'Contract Entitlement'!$D$4:$D$61,'Contract Entitlement'!$G$4:$G$61) -> 45817 | G7: =_xlfn.XLOOKUP(D7,'Contract Entitlement'!$D$4:$D$61,'Contract Entitlement'!$F$4:$F$61) -> 15 | H7: =IF(YEAR(E7)=2025,IF(DAY(E7)<15,CEILING(G7 * (12 - MONTH(E7) + 1) / 12,1),FLOOR(G7 * (12 - MONTH(E7) + 1) / 12,1)),IF(YEAR(E7)<2025,G7,0)) -> 9 | I7: =SUM(N7:Y7) -> 12 | J7: =COUNTIFS('2025 Time Off Request'!$A$2:$A$422,D7,'2025 Time Off Request'!$E$2:$E$422,"UNPAID") -> 6 | K7: =H7-I7 -> -3 | L7: =K7/G7 -> -0.2 | N7: =COUNTIFS('2025 Time Off Request'!$N$2:$N$422,N$1,'2025 Time Off Request'!$A$2:$A$422,$D7) -> 0 | O7: =COUNTIFS('2025 Time Off Request'!$N$2:$N$422,O$1,'2025 Time Off Request'!$A$2:$A$422,$D7) -> 0 | P7: =COUNTIFS('2025 Time Off Request'!$N$2:$N$422,P$1,'2025 Time Off Request'!$A$2:$A$422,$D7) -> 0 | Q7: =COUNTIFS('2025 Time Off Request'!$N$2:$N$422,Q$1,'2025 Time Off Request'!$A$2:$A$422,$D7) -> 0 | R7: =COUNTIFS('2025 Time Off Request'!$N$2:$N$422,R$1,'2025 Time Off Request'!$A$2:$A$422,$D7) -> 0 | S7: =COUNTIFS('2025 Time Off Request'!$N$2:$N$422,S$1,'2025 Time Off Request'!$A$2:$A$422,$D7) -> 1 | T7: =COUNTIFS('2025 Time Off Request'!$N$2:$N$422,T$1,'2025 Time Off Request'!$A$2:$A$422,$D7) -> 5 | U7: =COUNTIFS('2025 Time Off Request'!$N$2:$N$422,U$1,'2025 Time Off Request'!$A$2:$A$422,$D7) -> 0 | ... Y7: =COUNTIFS('2025 Time Off Request'!$N$2:$N$422,Y$1,'2025 Time Off Request'!$A$2:$A$422,$D7) -> 0
B8: ST | C8: Call Center Rep | D8: Pelius, Jacqulene | E8: =_xlfn.XLOOKUP(D8,'Contract Entitlement'!$D$4:$D$61,'Contract Entitlement'!$G$4:$G$61) -> 45855 | G8: =_xlfn.XLOOKUP(D8,'Contract Entitlement'!$D$4:$D$61,'Contract Entitlement'!$F$4:$F$61) -> 10 | H8: =IF(YEAR(E8)=2025,IF(DAY(E8)<15,CEILING(G8 * (12 - MONTH(E8) + 1) / 12,1),FLOOR(G8 * (12 - MONTH(E8) + 1) / 12,1)),IF(YEAR(E8)<2025,G8,0)) -> 5 | I8: =SUM(N8:Y8) -> 4 | J8: =COUNTIFS('2025 Time Off Request'!$A$2:$A$422,D8,'2025 Time Off Request'!$E$2:$E$422,"UNPAID") -> 0 | K8: =H8-I8 -> 1 | L8: =K8/G8 -> 0.1 | N8: =COUNTIFS('2025 Time Off Request'!$N$2:$N$422,N$1,'2025 Time Off Request'!$A$2:$A$422,$D8) -> 0 | O8: =COUNTIFS('2025 Time Off Request'!$N$2:$N$422,O$1,'2025 Time Off Request'!$A$2:$A$422,$D8) -> 0 | P8: =COUNTIFS('2025 Time Off Request'!$N$2:$N$422,P$1,'2025 Time Off Request'!$A$2:$A$422,$D8) -> 0 | Q8: =COUNTIFS('2025 Time Off Request'!$N$2:$N$422,Q$1,'2025 Time Off Request'!$A$2:$A$422,$D8) -> 0 | R8: =COUNTIFS('2025 Time Off Request'!$N$2:$N$422,R$1,'2025 Time Off Request'!$A$2:$A$422,$D8) -> 0 | S8: =COUNTIFS('2025 Time Off Request'!$N$2:$N$422,S$1,'2025 Time Off Request'!$A$2:$A$422,$D8) -> 0 | T8: =COUNTIFS('2025 Time Off Request'!$N$2:$N$422,T$1,'2025 Time Off Request'!$A$2:$A$422,$D8) -> 0 | U8: =COUNTIFS('2025 Time Off Request'!$N$2:$N$422,U$1,'2025 Time Off Request'!$A$2:$A$422,$D8) -> 0 | ... Y8: =COUNTIFS('2025 Time Off Request'!$N$2:$N$422,Y$1,'2025 Time Off Request'!$A$2:$A$422,$D8) -> 4
B9: ST | C9: Call Center Rep | D9: Black, Marijna Alida | E9: =_xlfn.XLOOKUP(D9,'Contract Entitlement'!$D$4:$D$61,'Contract Entitlement'!$G$4:$G$61) -> 45833 | G9: =_xlfn.XLOOKUP(D9,'Contract Entitlement'!$D$4:$D$61,'Contract Entitlement'!$F$4:$F$61) -> 10 | H9: =IF(YEAR(E9)=2025,IF(DAY(E9)<15,CEILING(G9 * (12 - MONTH(E9) + 1) / 12,1),FLOOR(G9 * (12 - MONTH(E9) + 1) / 12,1)),IF(YEAR(E9)<2025,G9,0)) -> 5 | I9: =SUM(N9:Y9) -> 2 | J9: =COUNTIFS('2025 Time Off Request'!$A$2:$A$422,D9,'2025 Time Off Request'!$E$2:$E$422,"UNPAID") -> 1 | K9: =H9-I9 -> 3 | L9: =K9/G9 -> 0.3 | N9: =COUNTIFS('2025 Time Off Request'!$N$2:$N$422,N$1,'2025 Time Off Request'!$A$2:$A$422,$D9) -> 0 | O9: =COUNTIFS('2025 Time Off Request'!$N$2:$N$422,O$1,'2025 Time Off Request'!$A$2:$A$422,$D9) -> 0 | P9: =COUNTIFS('2025 Time Off Request'!$N$2:$N$422,P$1,'2025 Time Off Request'!$A$2:$A$422,$D9) -> 0 | Q9: =COUNTIFS('2025 Time Off Request'!$N$2:$N$422,Q$1,'2025 Time Off Request'!$A$2:$A$422,$D9) -> 0 | R9: =COUNTIFS('2025 Time Off Request'!$N$2:$N$422,R$1,'2025 Time Off Request'!$A$2:$A$422,$D9) -> 0 | S9: =COUNTIFS('2025 Time Off Request'!$N$2:$N$422,S$1,'2025 Time Off Request'!$A$2:$A$422,$D9) -> 0 | T9: =COUNTIFS('2025 Time Off Request'!$N$2:$N$422,T$1,'2025 Time Off Request'!$A$2:$A$422,$D9) -> 0 | U9: =COUNTIFS('2025 Time Off Request'!$N$2:$N$422,U$1,'2025 Time Off Request'!$A$2:$A$422,$D9) -> 0 | ... Y9: =COUNTIFS('2025 Time Off Request'!$N$2:$N$422,Y$1,'2025 Time Off Request'!$A$2:$A$422,$D9) -> 1
B10: ST | C10: Call Center Rep | D10: Milankovic, Tatjana | E10: =_xlfn.XLOOKUP(D10,'Contract Entitlement'!$D$4:$D$61,'Contract Entitlement'!$G$4:$G$61) -> 45413 | G10: =_xlfn.XLOOKUP(D10,'Contract Entitlement'!$D$4:$D$61,'Contract Entitlement'!$F$4:$F$61) -> 10 | H10: =IF(YEAR(E10)=2025,IF(DAY(E10)<15,CEILING(G10 * (12 - MONTH(E10) + 1) / 12,1),FLOOR(G10 * (12 - MONTH(E10) + 1) / 12,1)),IF(YEAR(E10)<2025,G10,0)) -> 10 | I10: =SUM(N10:Y10) -> 6 | J10: =COUNTIFS('2025 Time Off Request'!$A$2:$A$422,D10,'2025 Time Off Request'!$E$2:$E$422,"UNPAID") -> 0 | K10: =H10-I10 -> 4 | L10: =K10/G10 -> 0.4 | N10: =COUNTIFS('2025 Time Off Request'!$N$2:$N$422,N$1,'2025 Time Off Request'!$A$2:$A$422,$D10) -> 0 | O10: =COUNTIFS('2025 Time Off Request'!$N$2:$N$422,O$1,'2025 Time Off Request'!$A$2:$A$422,$D10) -> 0 | P10: =COUNTIFS('2025 Time Off Request'!$N$2:$N$422,P$1,'2025 Time Off Request'!$A$2:$A$422,$D10) -> 0 | Q10: =COUNTIFS('2025 Time Off Request'!$N$2:$N$422,Q$1,'2025 Time Off Request'!$A$2:$A$422,$D10) -> 0 | R10: =COUNTIFS('2025 Time Off Request'!$N$2:$N$422,R$1,'2025 Time Off Request'!$A$2:$A$422,$D10) -> 6 | S10: =COUNTIFS('2025 Time Off Request'!$N$2:$N$422,S$1,'2025 Time Off Request'!$A$2:$A$422,$D10) -> 0 | T10: =COUNTIFS('2025 Time Off Request'!$N$2:$N$422,T$1,'2025 Time Off Request'!$A$2:$A$422,$D10) -> 0 | U10: =COUNTIFS('2025 Time Off Request'!$N$2:$N$422,U$1,'2025 Time Off Request'!$A$2:$A$422,$D10) -> 0 | ... Y10: =COUNTIFS('2025 Time Off Request'!$N$2:$N$422,Y$1,'2025 Time Off Request'!$A$2:$A$422,$D10) -> 0
